Workbook

Sheet كـشـف حضور يومي
A1: بـــيـــانـــات | C1: يناير | D1: 1 | J1: 1 | P1: 1 | V1: 1 | AB1: 1 | AH1: 1 | AN1: 1 | AT1: 1 | AZ1: 1 | BF1: 1 | BL1: 1 | BR1: 1 | BX1: 1 | CD1: 1 | CJ1: 1 | CP1: 1 | CV1: 1 | DB1: 1 | DH1: 1 | DN1: 1 | DT1: 1 | DZ1: 1 | EF1: 1 | EL1: 1 | ER1: 1 | EX1: 1 | FD1: 1 | FJ1: 1 | FP1: 1 | FV1: 1 | GB1: 1
D2: السبت | J2: السبت | P2: السبت | V2: السبت | AB2: السبت | AH2: السبت | AN2: السبت | AT2: السبت | AZ2: السبت | BF2: السبت | BL2: السبت | BR2: السبت | BX2: السبت | CD2: السبت | CJ2: السبت | CP2: السبت | CV2: السبت | DB2: السبت | DH2: السبت | DN2: السبت | DT2: السبت | DZ2: السبت | EF2: السبت | EL2: السبت | ER2: السبت | EX2: السبت | FD2: السبت | FJ2: السبت | FP2: السبت | FV2: السبت | GB2: السبت
A3: الإسم | B3: الوظيفة | C3: المشروع | D3: حضور | E3: انصراف | F3: إضافي | G3: خصم | H3: إجمالي | I3: ملاحظات | J3: حضور | K3: انصراف | L3: إضافي | M3: خصم | N3: إجمالي | O3: ملاحظات | P3: حضور | Q3: انصراف | R3: إضافي | S3: خصم | T3: إجمالي | U3: ملاحظات | V3: حضور | W3: انصراف | X3: إضافي | Y3: خصم | Z3: إجمالي | AA3: ملاحظات | AB3: حضور | AC3: انصراف | AD3: إضافي | AE3: خصم | AF3: إجمالي | AG3: ملاحظات | AH3: حضور | AI3: انصراف | AJ3: إضافي | AK3: خصم | AL3: إجمالي | AM3: ملاحظات | AN3: حضور | AO3: انصراف | AP3: إضافي | AQ3: خصم | AR3: إجمالي | AS3: ملاحظات | AT3: حضور | AU3: انصراف | AV3: إضافي | AW3: خصم | AX3: إجمالي | AY3: ملاحظات | AZ3: حضور | BA3: انصراف | BB3: إضافي | BC3: خصم | BD3: إجمالي | BE3: ملاحظات | BF3: حضور | BG3: انصراف | BH3: إضافي | BI3: خصم | BJ3: إجمالي | BK3: ملاحظات | BL3: حضور | BM3: انصراف | BN3: إضافي | BO3: خصم | BP3: إجمالي | BQ3: ملاحظات | BR3: حضور | BS3: انصراف | BT3: إضافي | BU3: خصم | BV3: إجمالي | BW3: ملاحظات | BX3: حضور | BY3: انصراف | BZ3: إضافي | CA3: خصم | CB3: إجمالي | CC3: ملاحظات | CD3: حضور | CE3: انصراف | CF3: إضافي | CG3: خصم | CH3: إجمالي | CI3: ملاحظات | CJ3: حضور | CK3: انصراف | CL3: إضافي | CM3: خصم | CN3: إجمالي | CO3: ملاحظات | CP3: حضور | CQ3: انصراف | CR3: إضافي | CS3: خصم | CT3: إجمالي | CU3: ملاحظات | CV3: حضور | CW3: انصراف | CX3: إضافي | CY3: خصم | CZ3: إجمالي | DA3: ملاحظات | DB3: حضور | DC3: انصراف | DD3: إضافي | DE3: خصم | DF3: إجمالي | DG3: ملاحظات | DH3: حضور | DI3: انصراف | DJ3: إضافي | DK3: خصم | DL3: إجمالي | DM3: ملاحظات | DN3: حضور | DO3: انصراف | DP3: إضافي | DQ3: خصم | DR3: إجمالي | DS3: ملاحظات | DT3: حضور | DU3: انصراف | DV3: إضافي | DW3: خصم | DX3: إجمالي | DY3: ملاحظات | DZ3: حضور | EA3: انصراف | EB3: إضافي | EC3: خصم | ED3: إجمالي | EE3: ملاحظات | EF3: حضور | EG3: انصراف | EH3: إضافي | EI3: خصم | EJ3: إجمالي | EK3: ملاحظات | EL3: حضور | EM3: انصراف | EN3: إضافي | EO3: خصم | EP3: إجمالي | EQ3: ملاحظات | ER3: حضور | ES3: انصراف | ET3: إضافي | EU3: خصم | EV3: إجمالي | EW3: ملاحظات | EX3: حضور | EY3: انصراف | EZ3: إضافي | FA3: خصم | FB3: إجمالي | FC3: ملاحظات | FD3: حضور | FE3: انصراف | FF3: إضافي | FG3: خصم | FH3: إجمالي | FI3: ملاحظات | FJ3: حضور | FK3: انصراف | FL3: إضافي | FM3: خصم | FN3: إجمالي | FO3: ملاحظات | FP3: حضور | FQ3: انصراف | FR3: إضافي | FS3: خصم | FT3: إجمالي | FU3: ملاحظات | FV3: حضور | FW3: انصراف | FX3: إضافي | FY3: خصم | FZ3: إجمالي | GA3: ملاحظات | GB3: حضور | GC3: انصراف | GD3: إضافي | GE3: خصم | GF3: إجمالي | GG3: ملاحظات
A4: كريم محمود | B4: سكرتير | C4: البنك الدولي | D4: 0.375 | E4: 0.70833333 | F4: =H4-مراجع!$B$2 -> 0 | G4: =مراجع!$B$2-H4 -> 0 | H4: =SUM(E4-D4) -> 0.33333333 | J4: 0.375 | K4: 0.70833333 | L4: =N4-مراجع!$B$2 -> 0 | M4: =مراجع!$B$2-N4 -> 0 | N4: =SUM(K4-J4) -> 0.33333333 | P4: 0.375 | Q4: 0.70833333 | R4: =T4-مراجع!$B$2 -> 0 | S4: =مراجع!$B$2-T4 -> 0 | T4: =SUM(Q4-P4) -> 0.33333333 | V4: 0.375 | W4: 0.70833333 | X4: =Z4-مراجع!$B$2 -> 0 | Y4: =مراجع!$B$2-Z4 -> 0 | Z4: =SUM(W4-V4) -> 0.33333333 | AB4: 0.375 | AC4: 0.70833333 | AD4: =AF4-مراجع!$B$2 -> 0 | AE4: =مراجع!$B$2-AF4 -> 0 | AF4: =SUM(AC4-AB4) -> 0.33333333 | AH4: 0.375 | AI4: 0.70833333 | AJ4: =AL4-مراجع!$B$2 -> 0 | AK4: =مراجع!$B$2-AL4 -> 0 | AL4: =SUM(AI4-AH4) -> 0.33333333 | AN4: 0.375 | AO4: 0.70833333 | AP4: =AR4-مراجع!$B$2 -> 0 | AQ4: =مراجع!$B$2-AR4 -> 0 | AR4: =SUM(AO4-AN4) -> 0.33333333 | AT4: 0.375 | AU4: 0.70833333 | AV4: =AX4-مراجع!$B$2 -> 0 | AW4: =مراجع!$B$2-AX4 -> 0 | AX4: =SUM(AU4-AT4) -> 0.33333333 | AZ4: 0.375 | BA4: 0.70833333 | BB4: =BD4-مراجع!$B$2 -> 0 | BC4: =مراجع!$B$2-BD4 -> 0 | BD4: =SUM(BA4-AZ4) -> 0.33333333 | BF4: 0.375 | BG4: 0.70833333 | BH4: =BJ4-مراجع!$B$2 -> 0 | BI4: =مراجع!$B$2-BJ4 -> 0 | BJ4: =SUM(BG4-BF4) -> 0.33333333 | BL4: 0.375 | BM4: 0.70833333 | BN4: =BP4-مراجع!$B$2 -> 0 | BO4: =مراجع!$B$2-BP4 -> 0 | BP4: =SUM(BM4-BL4) -> 0.33333333 | BR4: 0.375 | BS4: 0.70833333 | BT4: =BV4-مراجع!$B$2 -> 0 | BU4: =مراجع!$B$2-BV4 -> 0 | BV4: =SUM(BS4-BR4) -> 0.33333333 | BX4: 0.375 | BY4: 0.70833333 | BZ4: =CB4-مراجع!$B$2 -> 0 | CA4: =مراجع!$B$2-CB4 -> 0 | CB4: =SUM(BY4-BX4) -> 0.33333333 | CD4: 0.375 | CE4: 0.70833333 | CF4: =CH4-مراجع!$B$2 -> 0 | CG4: =مراجع!$B$2-CH4 -> 0 | CH4: =SUM(CE4-CD4) -> 0.33333333 | CJ4: 0.375 | CK4: 0.70833333 | CL4: =CN4-مراجع!$B$2 -> 0 | CM4: =مراجع!$B$2-CN4 -> 0 | CN4: =SUM(CK4-CJ4) -> 0.33333333 | CP4: 0.375 | CQ4: 0.70833333 | CR4: =CT4-مراجع!$B$2 -> 0 | CS4: =مراجع!$B$2-CT4 -> 0 | CT4: =SUM(CQ4-CP4) -> 0.33333333 | CV4: 0.375 | CW4: 0.70833333 | CX4: =CZ4-مراجع!$B$2 -> 0 | CY4: =مراجع!$B$2-CZ4 -> 0 | CZ4: =SUM(CW4-CV4) -> 0.33333333 | DB4: 0.375 | DC4: 0.70833333 | DD4: =DF4-مراجع!$B$2 -> 0 | DE4: =مراجع!$B$2-DF4 -> 0 | DF4: =SUM(DC4-DB4) -> 0.33333333 | DH4: 0.375 | DI4: 0.70833333 | DJ4: =DL4-مراجع!$B$2 -> 0 | DK4: =مراجع!$B$2-DL4 -> 0 | DL4: =SUM(DI4-DH4) -> 0.33333333 | DN4: 0.375 | DO4: 0.70833333 | DP4: =DR4-مراجع!$B$2 -> 0 | DQ4: =مراجع!$B$2-DR4 -> 0 | DR4: =SUM(DO4-DN4) -> 0.33333333 | DT4: 0.375 | DU4: 0.70833333 | DV4: =DX4-مراجع!$B$2 -> 0 | DW4: =مراجع!$B$2-DX4 -> 0 | DX4: =SUM(DU4-DT4) -> 0.33333333 | DZ4: 0.375 | EA4: 0.70833333 | EB4: =ED4-مراجع!$B$2 -> 0 | EC4: =مراجع!$B$2-ED4 -> 0 | ED4: =SUM(EA4-DZ4) -> 0.33333333 | EF4: 0.375 | EG4: 0.70833333 | EH4: =EJ4-مراجع!$B$2 -> 0 | EI4: =مراجع!$B$2-EJ4 -> 0 | EJ4: =SUM(EG4-EF4) -> 0.33333333 | EL4: 0.375 | EM4: 0.70833333 | EN4: =EP4-مراجع!$B$2 -> 0 | EO4: =مراجع!$B$2-EP4 -> 0 | EP4: =SUM(EM4-EL4) -> 0.33333333 | ER4: 0.375 | ES4: 0.70833333 | ET4: =EV4-مراجع!$B$2 -> 0 | EU4: =مراجع!$B$2-EV4 -> 0 | EV4: =SUM(ES4-ER4) -> 0.33333333 | EZ4: =FB4-مراجع!$B$2 -> -0.33333333 | FA4: =مراجع!$B$2-FB4 -> 0.33333333 | FB4: =SUM(EY4-EX4) -> 0 | FF4: =FH4-مراجع!$B$2 -> -0.33333333 | FG4: =مراجع!$B$2-FH4 -> 0.33333333 | FH4: =SUM(FE4-FD4) -> 0 | FL4: =FN4-مراجع!$B$2 -> -0.33333333 | FM4: =مراجع!$B$2-FN4 -> 0.33333333 | FN4: =SUM(FK4-FJ4) -> 0 | FR4: =FT4-مراجع!$B$2 -> -0.33333333 | FS4: =مراجع!$B$2-FT4 -> 0.33333333 | FT4: =SUM(FQ4-FP4) -> 0 | FX4: =FZ4-مراجع!$B$2 -> -0.33333333 | FY4: =مراجع!$B$2-FZ4 -> 0.33333333 | FZ4: =SUM(FW4-FV4) -> 0 | GD4: =GF4-مراجع!$B$2 -> -0.33333333 | GE4: =مراجع!$B$2-GF4 -> 0.33333333 | GF4: =SUM(GC4-GB4) -> 0
A5: عبد العزيز محمد | B5: محلل بيانات | C5: البنك الدولي | F5: =H5-مراجع!$B$2 -> -0.33333333 | G5: =مراجع!$B$2-H5 -> 0.33333333 | H5: =SUM(E5-D5) -> 0 | L5: =N5-مراجع!$B$2 -> -0.33333333 | M5: =مراجع!$B$2-N5 -> 0.33333333 | N5: =SUM(K5-J5) -> 0 | R5: =T5-مراجع!$B$2 -> -0.33333333 | S5: =مراجع!$B$2-T5 -> 0.33333333 | T5: =SUM(Q5-P5) -> 0 | X5: =Z5-مراجع!$B$2 -> -0.33333333 | Y5: =مراجع!$B$2-Z5 -> 0.33333333 | Z5: =SUM(W5-V5) -> 0 | AD5: =AF5-مراجع!$B$2 -> -0.33333333 | AE5: =مراجع!$B$2-AF5 -> 0.33333333 | AF5: =SUM(AC5-AB5) -> 0 | AJ5: =AL5-مراجع!$B$2 -> -0.33333333 | AK5: =مراجع!$B$2-AL5 -> 0.33333333 | AL5: =SUM(AI5-AH5) -> 0 | AP5: =AR5-مراجع!$B$2 -> -0.33333333 | AQ5: =مراجع!$B$2-AR5 -> 0.33333333 | AR5: =SUM(AO5-AN5) -> 0 | AV5: =AX5-مراجع!$B$2 -> -0.33333333 | AW5: =مراجع!$B$2-AX5 -> 0.33333333 | AX5: =SUM(AU5-AT5) -> 0 | BB5: =BD5-مراجع!$B$2 -> -0.33333333 | BC5: =مراجع!$B$2-BD5 -> 0.33333333 | BD5: =SUM(BA5-AZ5) -> 0 | BH5: =BJ5-مراجع!$B$2 -> -0.33333333 | BI5: =مراجع!$B$2-BJ5 -> 0.33333333 | BJ5: =SUM(BG5-BF5) -> 0 | BN5: =BP5-مراجع!$B$2 -> -0.33333333 | BO5: =مراجع!$B$2-BP5 -> 0.33333333 | BP5: =SUM(BM5-BL5) -> 0 | BT5: =BV5-مراجع!$B$2 -> -0.33333333 | BU5: =مراجع!$B$2-BV5 -> 0.33333333 | BV5: =SUM(BS5-BR5) -> 0 | BZ5: =CB5-مراجع!$B$2 -> -0.33333333 | CA5: =مراجع!$B$2-CB5 -> 0.33333333 | CB5: =SUM(BY5-BX5) -> 0 | CF5: =CH5-مراجع!$B$2 -> -0.33333333 | CG5: =مراجع!$B$2-CH5 -> 0.33333333 | CH5: =SUM(CE5-CD5) -> 0 | CL5: =CN5-مراجع!$B$2 -> -0.33333333 | CM5: =مراجع!$B$2-CN5 -> 0.33333333 | CN5: =SUM(CK5-CJ5) -> 0 | CR5: =CT5-مراجع!$B$2 -> -0.33333333 | CS5: =مراجع!$B$2-CT5 -> 0.33333333 | CT5: =SUM(CQ5-CP5) -> 0 | CX5: =CZ5-مراجع!$B$2 -> -0.33333333 | CY5: =مراجع!$B$2-CZ5 -> 0.33333333 | CZ5: =SUM(CW5-CV5) -> 0 | DD5: =DF5-مراجع!$B$2 -> -0.33333333 | DE5: =مراجع!$B$2-DF5 -> 0.33333333 | DF5: =SUM(DC5-DB5) -> 0 | DJ5: =DL5-مراجع!$B$2 -> -0.33333333 | DK5: =مراجع!$B$2-DL5 -> 0.33333333 | DL5: =SUM(DI5-DH5) -> 0 | DP5: =DR5-مراجع!$B$2 -> -0.33333333 | DQ5: =مراجع!$B$2-DR5 -> 0.33333333 | DR5: =SUM(DO5-DN5) -> 0 | DV5: =DX5-مراجع!$B$2 -> -0.33333333 | DW5: =مراجع!$B$2-DX5 -> 0.33333333 | DX5: =SUM(DU5-DT5) -> 0 | EB5: =ED5-مراجع!$B$2 -> -0.33333333 | EC5: =مراجع!$B$2-ED5 -> 0.33333333 | ED5: =SUM(EA5-DZ5) -> 0 | EH5: =EJ5-مراجع!$B$2 -> -0.33333333 | EI5: =مراجع!$B$2-EJ5 -> 0.33333333 | EJ5: =SUM(EG5-EF5) -> 0 | EN5: =EP5-مراجع!$B$2 -> -0.33333333 | EO5: =مراجع!$B$2-EP5 -> 0.33333333 | EP5: =SUM(EM5-EL5) -> 0 | ET5: =EV5-مراجع!$B$2 -> -0.33333333 | EU5: =مراجع!$B$2-EV5 -> 0.33333333 | EV5: =SUM(ES5-ER5) -> 0 | EZ5: =FB5-مراجع!$B$2 -> -0.33333333 | FA5: =مراجع!$B$2-FB5 -> 0.33333333 | FB5: =SUM(EY5-EX5) -> 0 | FF5: =FH5-مراجع!$B$2 -> -0.33333333 | FG5: =مراجع!$B$2-FH5 -> 0.33333333 | FH5: =SUM(FE5-FD5) -> 0 | FL5: =FN5-مراجع!$B$2 -> -0.33333333 | FM5: =مراجع!$B$2-FN5 -> 0.33333333 | FN5: =SUM(FK5-FJ5) -> 0 | FR5: =FT5-مراجع!$B$2 -> -0.33333333 | FS5: =مراجع!$B$2-FT5 -> 0.33333333 | FT5: =SUM(FQ5-FP5) -> 0 | FX5: =FZ5-مراجع!$B$2 -> -0.33333333 | FY5: =مراجع!$B$2-FZ5 -> 0.33333333 | FZ5: =SUM(FW5-FV5) -> 0 | GD5: =GF5-مراجع!$B$2 -> -0.33333333 | GE5: =مراجع!$B$2-GF5 -> 0.33333333 | GF5: =SUM(GC5-GB5) -> 0
A6: محمد حسين | B6: محاسب | C6: البنك الدولي | F6: =H6-مراجع!$B$2 -> -0.33333333 | G6: =مراجع!$B$2-H6 -> 0.33333333 | H6: =SUM(E6-D6) -> 0 | L6: =N6-مراجع!$B$2 -> -0.33333333 | M6: =مراجع!$B$2-N6 -> 0.33333333 | N6: =SUM(K6-J6) -> 0 | R6: =T6-مراجع!$B$2 -> -0.33333333 | S6: =مراجع!$B$2-T6 -> 0.33333333 | T6: =SUM(Q6-P6) -> 0 | X6: =Z6-مراجع!$B$2 -> -0.33333333 | Y6: =مراجع!$B$2-Z6 -> 0.33333333 | Z6: =SUM(W6-V6) -> 0 | AD6: =AF6-مراجع!$B$2 -> -0.33333333 | AE6: =مراجع!$B$2-AF6 -> 0.33333333 | AF6: =SUM(AC6-AB6) -> 0 | AJ6: =AL6-مراجع!$B$2 -> -0.33333333 | AK6: =مراجع!$B$2-AL6 -> 0.33333333 | AL6: =SUM(AI6-AH6) -> 0 | AP6: =AR6-مراجع!$B$2 -> -0.33333333 | AQ6: =مراجع!$B$2-AR6 -> 0.33333333 | AR6: =SUM(AO6-AN6) -> 0 | AV6: =AX6-مراجع!$B$2 -> -0.33333333 | AW6: =مراجع!$B$2-AX6 -> 0.33333333 | AX6: =SUM(AU6-AT6) -> 0 | BB6: =BD6-مراجع!$B$2 -> -0.33333333 | BC6: =مراجع!$B$2-BD6 -> 0.33333333 | BD6: =SUM(BA6-AZ6) -> 0 | BH6: =BJ6-مراجع!$B$2 -> -0.33333333 | BI6: =مراجع!$B$2-BJ6 -> 0.33333333 | BJ6: =SUM(BG6-BF6) -> 0 | BN6: =BP6-مراجع!$B$2 -> -0.33333333 | BO6: =مراجع!$B$2-BP6 -> 0.33333333 | BP6: =SUM(BM6-BL6) -> 0 | BT6: =BV6-مراجع!$B$2 -> -0.33333333 | BU6: =مراجع!$B$2-BV6 -> 0.33333333 | BV6: =SUM(BS6-BR6) -> 0 | BZ6: =CB6-مراجع!$B$2 -> -0.33333333 | CA6: =مراجع!$B$2-CB6 -> 0.33333333 | CB6: =SUM(BY6-BX6) -> 0 | CF6: =CH6-مراجع!$B$2 -> -0.33333333 | CG6: =مراجع!$B$2-CH6 -> 0.33333333 | CH6: =SUM(CE6-CD6) -> 0 | CL6: =CN6-مراجع!$B$2 -> -0.33333333 | CM6: =مراجع!$B$2-CN6 -> 0.33333333 | CN6: =SUM(CK6-CJ6) -> 0 | CR6: =CT6-مراجع!$B$2 -> -0.33333333 | CS6: =مراجع!$B$2-CT6 -> 0.33333333 | CT6: =SUM(CQ6-CP6) -> 0 | CX6: =CZ6-مراجع!$B$2 -> -0.33333333 | CY6: =مراجع!$B$2-CZ6 -> 0.33333333 | CZ6: =SUM(CW6-CV6) -> 0 | DD6: =DF6-مراجع!$B$2 -> -0.33333333 | DE6: =مراجع!$B$2-DF6 -> 0.33333333 | DF6: =SUM(DC6-DB6) -> 0 | DJ6: =DL6-مراجع!$B$2 -> -0.33333333 | DK6: =مراجع!$B$2-DL6 -> 0.33333333 | DL6: =SUM(DI6-DH6) -> 0 | DP6: =DR6-مراجع!$B$2 -> -0.33333333 | DQ6: =مراجع!$B$2-DR6 -> 0.33333333 | DR6: =SUM(DO6-DN6) -> 0 | DV6: =DX6-مراجع!$B$2 -> -0.33333333 | DW6: =مراجع!$B$2-DX6 -> 0.33333333 | DX6: =SUM(DU6-DT6) -> 0 | EB6: =ED6-مراجع!$B$2 -> -0.33333333 | EC6: =مراجع!$B$2-ED6 -> 0.33333333 | ED6: =SUM(EA6-DZ6) -> 0 | EH6: =EJ6-مراجع!$B$2 -> -0.33333333 | EI6: =مراجع!$B$2-EJ6 -> 0.33333333 | EJ6: =SUM(EG6-EF6) -> 0 | EN6: =EP6-مراجع!$B$2 -> -0.33333333 | EO6: =مراجع!$B$2-EP6 -> 0.33333333 | EP6: =SUM(EM6-EL6) -> 0 | ET6: =EV6-مراجع!$B$2 -> -0.33333333 | EU6: =مراجع!$B$2-EV6 -> 0.33333333 | EV6: =SUM(ES6-ER6) -> 0 | EZ6: =FB6-مراجع!$B$2 -> -0.33333333 | FA6: =مراجع!$B$2-FB6 -> 0.33333333 | FB6: =SUM(EY6-EX6) -> 0 | FF6: =FH6-مراجع!$B$2 -> -0.33333333 | FG6: =مراجع!$B$2-FH6 -> 0.33333333 | FH6: =SUM(FE6-FD6) -> 0 | FL6: =FN6-مراجع!$B$2 -> -0.33333333 | FM6: =مراجع!$B$2-FN6 -> 0.33333333 | FN6: =SUM(FK6-FJ6) -> 0 | FR6: =FT6-مراجع!$B$2 -> -0.33333333 | FS6: =مراجع!$B$2-FT6 -> 0.33333333 | FT6: =SUM(FQ6-FP6) -> 0 | FX6: =FZ6-مراجع!$B$2 -> -0.33333333 | FY6: =مراجع!$B$2-FZ6 -> 0.33333333 | FZ6: =SUM(FW6-FV6) -> 0 | GD6: =GF6-مراجع!$B$2 -> -0.33333333 | GE6: =مراجع!$B$2-GF6 -> 0.33333333 | GF6: =SUM(GC6-GB6) -> 0
A7: هالة محمود | B7: مسئول قواعد بيانات | C7: القرض الفرنسي | F7: =H7-مراجع!$B$2 -> -0.33333333 | G7: =مراجع!$B$2-H7 -> 0.33333333 | H7: =SUM(E7-D7) -> 0 | L7: =N7-مراجع!$B$2 -> -0.33333333 | M7: =مراجع!$B$2-N7 -> 0.33333333 | N7: =SUM(K7-J7) -> 0 | R7: =T7-مراجع!$B$2 -> -0.33333333 | S7: =مراجع!$B$2-T7 -> 0.33333333 | T7: =SUM(Q7-P7) -> 0 | X7: =Z7-مراجع!$B$2 -> -0.33333333 | Y7: =مراجع!$B$2-Z7 -> 0.33333333 | Z7: =SUM(W7-V7) -> 0 | AD7: =AF7-مراجع!$B$2 -> -0.33333333 | AE7: =مراجع!$B$2-AF7 -> 0.33333333 | AF7: =SUM(AC7-AB7) -> 0 | AJ7: =AL7-مراجع!$B$2 -> -0.33333333 | AK7: =مراجع!$B$2-AL7 -> 0.33333333 | AL7: =SUM(AI7-AH7) -> 0 | AP7: =AR7-مراجع!$B$2 -> -0.33333333 | AQ7: =مراجع!$B$2-AR7 -> 0.33333333 | AR7: =SUM(AO7-AN7) -> 0 | AV7: =AX7-مراجع!$B$2 -> -0.33333333 | AW7: =مراجع!$B$2-AX7 -> 0.33333333 | AX7: =SUM(AU7-AT7) -> 0 | BB7: =BD7-مراجع!$B$2 -> -0.33333333 | BC7: =مراجع!$B$2-BD7 -> 0.33333333 | BD7: =SUM(BA7-AZ7) -> 0 | BH7: =BJ7-مراجع!$B$2 -> -0.33333333 | BI7: =مراجع!$B$2-BJ7 -> 0.33333333 | BJ7: =SUM(BG7-BF7) -> 0 | BN7: =BP7-مراجع!$B$2 -> -0.33333333 | BO7: =مراجع!$B$2-BP7 -> 0.33333333 | BP7: =SUM(BM7-BL7) -> 0 | BT7: =BV7-مراجع!$B$2 -> -0.33333333 | BU7: =مراجع!$B$2-BV7 -> 0.33333333 | BV7: =SUM(BS7-BR7) -> 0 | BZ7: =CB7-مراجع!$B$2 -> -0.33333333 | CA7: =مراجع!$B$2-CB7 -> 0.33333333 | CB7: =SUM(BY7-BX7) -> 0 | CF7: =CH7-مراجع!$B$2 -> -0.33333333 | CG7: =مراجع!$B$2-CH7 -> 0.33333333 | CH7: =SUM(CE7-CD7) -> 0 | CL7: =CN7-مراجع!$B$2 -> -0.33333333 | CM7: =مراجع!$B$2-CN7 -> 0.33333333 | CN7: =SUM(CK7-CJ7) -> 0 | CR7: =CT7-مراجع!$B$2 -> -0.33333333 | CS7: =مراجع!$B$2-CT7 -> 0.33333333 | CT7: =SUM(CQ7-CP7) -> 0 | CX7: =CZ7-مراجع!$B$2 -> -0.33333333 | CY7: =مراجع!$B$2-CZ7 -> 0.33333333 | CZ7: =SUM(CW7-CV7) -> 0 | DD7: =DF7-مراجع!$B$2 -> -0.33333333 | DE7: =مراجع!$B$2-DF7 -> 0.33333333 | DF7: =SUM(DC7-DB7) -> 0 | DJ7: =DL7-مراجع!$B$2 -> -0.33333333 | DK7: =مراجع!$B$2-DL7 -> 0.33333333 | DL7: =SUM(DI7-DH7) -> 0 | DP7: =DR7-مراجع!$B$2 -> -0.33333333 | DQ7: =مراجع!$B$2-DR7 -> 0.33333333 | DR7: =SUM(DO7-DN7) -> 0 | DV7: =DX7-مراجع!$B$2 -> -0.33333333 | DW7: =مراجع!$B$2-DX7 -> 0.33333333 | DX7: =SUM(DU7-DT7) -> 0 | EB7: =ED7-مراجع!$B$2 -> -0.33333333 | EC7: =مراجع!$B$2-ED7 -> 0.33333333 | ED7: =SUM(EA7-DZ7) -> 0 | EH7: =EJ7-مراجع!$B$2 -> -0.33333333 | EI7: =مراجع!$B$2-EJ7 -> 0.33333333 | EJ7: =SUM(EG7-EF7) -> 0 | EN7: =EP7-مراجع!$B$2 -> -0.33333333 | EO7: =مراجع!$B$2-EP7 -> 0.33333333 | EP7: =SUM(EM7-EL7) -> 0 | ET7: =EV7-مراجع!$B$2 -> -0.33333333 | EU7: =مراجع!$B$2-EV7 -> 0.33333333 | EV7: =SUM(ES7-ER7) -> 0 | EZ7: =FB7-مراجع!$B$2 -> -0.33333333 | FA7: =مراجع!$B$2-FB7 -> 0.33333333 | FB7: =SUM(EY7-EX7) -> 0 | FF7: =FH7-مراجع!$B$2 -> -0.33333333 | FG7: =مراجع!$B$2-FH7 -> 0.33333333 | FH7: =SUM(FE7-FD7) -> 0 | FL7: =FN7-مراجع!$B$2 -> -0.33333333 | FM7: =مراجع!$B$2-FN7 -> 0.33333333 | FN7: =SUM(FK7-FJ7) -> 0 | FR7: =FT7-مراجع!$B$2 -> -0.33333333 | FS7: =مراجع!$B$2-FT7 -> 0.33333333 | FT7: =SUM(FQ7-FP7) -> 0 | FX7: =FZ7-مراجع!$B$2 -> -0.33333333 | FY7: =مراجع!$B$2-FZ7 -> 0.33333333 | FZ7: =SUM(FW7-FV7) -> 0 | GD7: =GF7-مراجع!$B$2 -> -0.33333333 | GE7: =مراجع!$B$2-GF7 -> 0.33333333 | GF7: =SUM(GC7-GB7) -> 0
A8: إسلام محمد | B8: منسق مشروع | C8: البنك الدولي | F8: =H8-مراجع!$B$2 -> -0.33333333 | G8: =مراجع!$B$2-H8 -> 0.33333333 | H8: =SUM(E8-D8) -> 0 | L8: =N8-مراجع!$B$2 -> -0.33333333 | M8: =مراجع!$B$2-N8 -> 0.33333333 | N8: =SUM(K8-J8) -> 0 | R8: =T8-مراجع!$B$2 -> -0.33333333 | S8: =مراجع!$B$2-T8 -> 0.33333333 | T8: =SUM(Q8-P8) -> 0 | X8: =Z8-مراجع!$B$2 -> -0.33333333 | Y8: =مراجع!$B$2-Z8 -> 0.33333333 | Z8: =SUM(W8-V8) -> 0 | AD8: =AF8-مراجع!$B$2 -> -0.33333333 | AE8: =مراجع!$B$2-AF8 -> 0.33333333 | AF8: =SUM(AC8-AB8) -> 0 | AJ8: =AL8-مراجع!$B$2 -> -0.33333333 | AK8: =مراجع!$B$2-AL8 -> 0.33333333 | AL8: =SUM(AI8-AH8) -> 0 | AP8: =AR8-مراجع!$B$2 -> -0.33333333 | AQ8: =مراجع!$B$2-AR8 -> 0.33333333 | AR8: =SUM(AO8-AN8) -> 0 | AV8: =AX8-مراجع!$B$2 -> -0.33333333 | AW8: =مراجع!$B$2-AX8 -> 0.33333333 | AX8: =SUM(AU8-AT8) -> 0 | BB8: =BD8-مراجع!$B$2 -> -0.33333333 | BC8: =مراجع!$B$2-BD8 -> 0.33333333 | BD8: =SUM(BA8-AZ8) -> 0 | BH8: =BJ8-مراجع!$B$2 -> -0.33333333 | BI8: =مراجع!$B$2-BJ8 -> 0.33333333 | BJ8: =SUM(BG8-BF8) -> 0 | BN8: =BP8-مراجع!$B$2 -> -0.33333333 | BO8: =مراجع!$B$2-BP8 -> 0.33333333 | BP8: =SUM(BM8-BL8) -> 0 | BT8: =BV8-مراجع!$B$2 -> -0.33333333 | BU8: =مراجع!$B$2-BV8 -> 0.33333333 | BV8: =SUM(BS8-BR8) -> 0 | BZ8: =CB8-مراجع!$B$2 -> -0.33333333 | CA8: =مراجع!$B$2-CB8 -> 0.33333333 | CB8: =SUM(BY8-BX8) -> 0 | CF8: =CH8-مراجع!$B$2 -> -0.33333333 | CG8: =مراجع!$B$2-CH8 -> 0.33333333 | CH8: =SUM(CE8-CD8) -> 0 | CL8: =CN8-مراجع!$B$2 -> -0.33333333 | CM8: =مراجع!$B$2-CN8 -> 0.33333333 | CN8: =SUM(CK8-CJ8) -> 0 | CR8: =CT8-مراجع!$B$2 -> -0.33333333 | CS8: =مراجع!$B$2-CT8 -> 0.33333333 | CT8: =SUM(CQ8-CP8) -> 0 | CX8: =CZ8-مراجع!$B$2 -> -0.33333333 | CY8: =مراجع!$B$2-CZ8 -> 0.33333333 | CZ8: =SUM(CW8-CV8) -> 0 | DD8: =DF8-مراجع!$B$2 -> -0.33333333 | DE8: =مراجع!$B$2-DF8 -> 0.33333333 | DF8: =SUM(DC8-DB8) -> 0 | DJ8: =DL8-مراجع!$B$2 -> -0.33333333 | DK8: =مراجع!$B$2-DL8 -> 0.33333333 | DL8: =SUM(DI8-DH8) -> 0 | DP8: =DR8-مراجع!$B$2 -> -0.33333333 | DQ8: =مراجع!$B$2-DR8 -> 0.33333333 | DR8: =SUM(DO8-DN8) -> 0 | DV8: =DX8-مراجع!$B$2 -> -0.33333333 | DW8: =مراجع!$B$2-DX8 -> 0.33333333 | DX8: =SUM(DU8-DT8) -> 0 | EB8: =ED8-مراجع!$B$2 -> -0.33333333 | EC8: =مراجع!$B$2-ED8 -> 0.33333333 | ED8: =SUM(EA8-DZ8) -> 0 | EH8: =EJ8-مراجع!$B$2 -> -0.33333333 | EI8: =مراجع!$B$2-EJ8 -> 0.33333333 | EJ8: =SUM(EG8-EF8) -> 0 | EN8: =EP8-مراجع!$B$2 -> -0.33333333 | EO8: =مراجع!$B$2-EP8 -> 0.33333333 | EP8: =SUM(EM8-EL8) -> 0 | ET8: =EV8-مراجع!$B$2 -> -0.33333333 | EU8: =مراجع!$B$2-EV8 -> 0.33333333 | EV8: =SUM(ES8-ER8) -> 0 | EZ8: =FB8-مراجع!$B$2 -> -0.33333333 | FA8: =مراجع!$B$2-FB8 -> 0.33333333 | FB8: =SUM(EY8-EX8) -> 0 | FF8: =FH8-مراجع!$B$2 -> -0.33333333 | FG8: =مراجع!$B$2-FH8 -> 0.33333333 | FH8: =SUM(FE8-FD8) -> 0 | FL8: =FN8-مراجع!$B$2 -> -0.33333333 | FM8: =مراجع!$B$2-FN8 -> 0.33333333 | FN8: =SUM(FK8-FJ8) -> 0 | FR8: =FT8-مراجع!$B$2 -> -0.33333333 | FS8: =مراجع!$B$2-FT8 -> 0.33333333 | FT8: =SUM(FQ8-FP8) -> 0 | FX8: =FZ8-مراجع!$B$2 -> -0.33333333 | FY8: =مراجع!$B$2-FZ8 -> 0.33333333 | FZ8: =SUM(FW8-FV8) -> 0 | GD8: =GF8-مراجع!$B$2 -> -0.33333333 | GE8: =مراجع!$B$2-GF8 -> 0.33333333 | GF8: =SUM(GC8-GB8) -> 0
A9: أحمد عبد المنعم | B9: محاسب | C9: البنك الدولي | F9: =H9-مراجع!$B$2 -> -0.33333333 | G9: =مراجع!$B$2-H9 -> 0.33333333 | H9: =SUM(E9-D9) -> 0 | L9: =N9-مراجع!$B$2 -> -0.33333333 | M9: =مراجع!$B$2-N9 -> 0.33333333 | N9: =SUM(K9-J9) -> 0 | R9: =T9-مراجع!$B$2 -> -0.33333333 | S9: =مراجع!$B$2-T9 -> 0.33333333 | T9: =SUM(Q9-P9) -> 0 | X9: =Z9-مراجع!$B$2 -> -0.33333333 | Y9: =مراجع!$B$2-Z9 -> 0.33333333 | Z9: =SUM(W9-V9) -> 0 | AD9: =AF9-مراجع!$B$2 -> -0.33333333 | AE9: =مراجع!$B$2-AF9 -> 0.33333333 | AF9: =SUM(AC9-AB9) -> 0 | AJ9: =AL9-مراجع!$B$2 -> -0.33333333 | AK9: =مراجع!$B$2-AL9 -> 0.33333333 | AL9: =SUM(AI9-AH9) -> 0 | AP9: =AR9-مراجع!$B$2 -> -0.33333333 | AQ9: =مراجع!$B$2-AR9 -> 0.33333333 | AR9: =SUM(AO9-AN9) -> 0 | AV9: =AX9-مراجع!$B$2 -> -0.33333333 | AW9: =مراجع!$B$2-AX9 -> 0.33333333 | AX9: =SUM(AU9-AT9) -> 0 | BB9: =BD9-مراجع!$B$2 -> -0.33333333 | BC9: =مراجع!$B$2-BD9 -> 0.33333333 | BD9: =SUM(BA9-AZ9) -> 0 | BH9: =BJ9-مراجع!$B$2 -> -0.33333333 | BI9: =مراجع!$B$2-BJ9 -> 0.33333333 | BJ9: =SUM(BG9-BF9) -> 0 | BN9: =BP9-مراجع!$B$2 -> -0.33333333 | BO9: =مراجع!$B$2-BP9 -> 0.33333333 | BP9: =SUM(BM9-BL9) -> 0 | BT9: =BV9-مراجع!$B$2 -> -0.33333333 | BU9: =مراجع!$B$2-BV9 -> 0.33333333 | BV9: =SUM(BS9-BR9) -> 0 | BZ9: =CB9-مراجع!$B$2 -> -0.33333333 | CA9: =مراجع!$B$2-CB9 -> 0.33333333 | CB9: =SUM(BY9-BX9) -> 0 | CF9: =CH9-مراجع!$B$2 -> -0.33333333 | CG9: =مراجع!$B$2-CH9 -> 0.33333333 | CH9: =SUM(CE9-CD9) -> 0 | CL9: =CN9-مراجع!$B$2 -> -0.33333333 | CM9: =مراجع!$B$2-CN9 -> 0.33333333 | CN9: =SUM(CK9-CJ9) -> 0 | CR9: =CT9-مراجع!$B$2 -> -0.33333333 | CS9: =مراجع!$B$2-CT9 -> 0.33333333 | CT9: =SUM(CQ9-CP9) -> 0 | CX9: =CZ9-مراجع!$B$2 -> -0.33333333 | CY9: =مراجع!$B$2-CZ9 -> 0.33333333 | CZ9: =SUM(CW9-CV9) -> 0 | DD9: =DF9-مراجع!$B$2 -> -0.33333333 | DE9: =مراجع!$B$2-DF9 -> 0.33333333 | DF9: =SUM(DC9-DB9) -> 0 | DJ9: =DL9-مراجع!$B$2 -> -0.33333333 | DK9: =مراجع!$B$2-DL9 -> 0.33333333 | DL9: =SUM(DI9-DH9) -> 0 | DP9: =DR9-مراجع!$B$2 -> -0.33333333 | DQ9: =مراجع!$B$2-DR9 -> 0.33333333 | DR9: =SUM(DO9-DN9) -> 0 | DV9: =DX9-مراجع!$B$2 -> -0.33333333 | DW9: =مراجع!$B$2-DX9 -> 0.33333333 | DX9: =SUM(DU9-DT9) -> 0 | EB9: =ED9-مراجع!$B$2 -> -0.33333333 | EC9: =مراجع!$B$2-ED9 -> 0.33333333 | ED9: =SUM(EA9-DZ9) -> 0 | EH9: =EJ9-مراجع!$B$2 -> -0.33333333 | EI9: =مراجع!$B$2-EJ9 -> 0.33333333 | EJ9: =SUM(EG9-EF9) -> 0 | EN9: =EP9-مراجع!$B$2 -> -0.33333333 | EO9: =مراجع!$B$2-EP9 -> 0.33333333 | EP9: =SUM(EM9-EL9) -> 0 | ET9: =EV9-مراجع!$B$2 -> -0.33333333 | EU9: =مراجع!$B$2-EV9 -> 0.33333333 | EV9: =SUM(ES9-ER9) -> 0 | EZ9: =FB9-مراجع!$B$2 -> -0.33333333 | FA9: =مراجع!$B$2-FB9 -> 0.33333333 | FB9: =SUM(EY9-EX9) -> 0 | FF9: =FH9-مراجع!$B$2 -> -0.33333333 | FG9: =مراجع!$B$2-FH9 -> 0.33333333 | FH9: =SUM(FE9-FD9) -> 0 | FL9: =FN9-مراجع!$B$2 -> -0.33333333 | FM9: =مراجع!$B$2-FN9 -> 0.33333333 | FN9: =SUM(FK9-FJ9) -> 0 | FR9: =FT9-مراجع!$B$2 -> -0.33333333 | FS9: =مراجع!$B$2-FT9 -> 0.33333333 | FT9: =SUM(FQ9-FP9) -> 0 | FX9: =FZ9-مراجع!$B$2 -> -0.33333333 | FY9: =مراجع!$B$2-FZ9 -> 0.33333333 | FZ9: =SUM(FW9-FV9) -> 0 | GD9: =GF9-مراجع!$B$2 -> -0.33333333 | GE9: =مراجع!$B$2-GF9 -> 0.33333333 | GF9: =SUM(GC9-GB9) -> 0
A10: هاجر أحمد | B10: مسئول قواعد بيانات | C10: القرض الفرنسي | F10: =H10-مراجع!$B$2 -> -0.33333333 | G10: =مراجع!$B$2-H10 -> 0.33333333 | H10: =SUM(E10-D10) -> 0 | L10: =N10-مراجع!$B$2 -> -0.33333333 | M10: =مراجع!$B$2-N10 -> 0.33333333 | N10: =SUM(K10-J10) -> 0 | R10: =T10-مراجع!$B$2 -> -0.33333333 | S10: =مراجع!$B$2-T10 -> 0.33333333 | T10: =SUM(Q10-P10) -> 0 | X10: =Z10-مراجع!$B$2 -> -0.33333333 | Y10: =مراجع!$B$2-Z10 -> 0.33333333 | Z10: =SUM(W10-V10) -> 0 | AD10: =AF10-مراجع!$B$2 -> -0.33333333 | AE10: =مراجع!$B$2-AF10 -> 0.33333333 | AF10: =SUM(AC10-AB10) -> 0 | AJ10: =AL10-مراجع!$B$2 -> -0.33333333 | AK10: =مراجع!$B$2-AL10 -> 0.33333333 | AL10: =SUM(AI10-AH10) -> 0 | AP10: =AR10-مراجع!$B$2 -> -0.33333333 | AQ10: =مراجع!$B$2-AR10 -> 0.33333333 | AR10: =SUM(AO10-AN10) -> 0 | AV10: =AX10-مراجع!$B$2 -> -0.33333333 | AW10: =مراجع!$B$2-AX10 -> 0.33333333 | AX10: =SUM(AU10-AT10) -> 0 | BB10: =BD10-مراجع!$B$2 -> -0.33333333 | BC10: =مراجع!$B$2-BD10 -> 0.33333333 | BD10: =SUM(BA10-AZ10) -> 0 | BH10: =BJ10-مراجع!$B$2 -> -0.33333333 | BI10: =مراجع!$B$2-BJ10 -> 0.33333333 | BJ10: =SUM(BG10-BF10) -> 0 | BN10: =BP10-مراجع!$B$2 -> -0.33333333 | BO10: =مراجع!$B$2-BP10 -> 0.33333333 | BP10: =SUM(BM10-BL10) -> 0 | BT10: =BV10-مراجع!$B$2 -> -0.33333333 | BU10: =مراجع!$B$2-BV10 -> 0.33333333 | BV10: =SUM(BS10-BR10) -> 0 | BZ10: =CB10-مراجع!$B$2 -> -0.33333333 | CA10: =مراجع!$B$2-CB10 -> 0.33333333 | CB10: =SUM(BY10-BX10) -> 0 | CF10: =CH10-مراجع!$B$2 -> -0.33333333 | CG10: =مراجع!$B$2-CH10 -> 0.33333333 | CH10: =SUM(CE10-CD10) -> 0 | CL10: =CN10-مراجع!$B$2 -> -0.33333333 | CM10: =مراجع!$B$2-CN10 -> 0.33333333 | CN10: =SUM(CK10-CJ10) -> 0 | CR10: =CT10-مراجع!$B$2 -> -0.33333333 | CS10: =مراجع!$B$2-CT10 -> 0.33333333 | CT10: =SUM(CQ10-CP10) -> 0 | CX10: =CZ10-مراجع!$B$2 -> -0.33333333 | CY10: =مراجع!$B$2-CZ10 -> 0.33333333 | CZ10: =SUM(CW10-CV10) -> 0 | DD10: =DF10-مراجع!$B$2 -> -0.33333333 | DE10: =مراجع!$B$2-DF10 -> 0.33333333 | DF10: =SUM(DC10-DB10) -> 0 | DJ10: =DL10-مراجع!$B$2 -> -0.33333333 | DK10: =مراجع!$B$2-DL10 -> 0.33333333 | DL10: =SUM(DI10-DH10) -> 0 | DP10: =DR10-مراجع!$B$2 -> -0.33333333 | DQ10: =مراجع!$B$2-DR10 -> 0.33333333 | DR10: =SUM(DO10-DN10) -> 0 | DV10: =DX10-مراجع!$B$2 -> -0.33333333 | DW10: =مراجع!$B$2-DX10 -> 0.33333333 | DX10: =SUM(DU10-DT10) -> 0 | EB10: =ED10-مراجع!$B$2 -> -0.33333333 | EC10: =مراجع!$B$2-ED10 -> 0.33333333 | ED10: =SUM(EA10-DZ10) -> 0 | EH10: =EJ10-مراجع!$B$2 -> -0.33333333 | EI10: =مراجع!$B$2-EJ10 -> 0.33333333 | EJ10: =SUM(EG10-EF10) -> 0 | EN10: =EP10-مراجع!$B$2 -> -0.33333333 | EO10: =مراجع!$B$2-EP10 -> 0.33333333 | EP10: =SUM(EM10-EL10) -> 0 | ET10: =EV10-مراجع!$B$2 -> -0.33333333 | EU10: =مراجع!$B$2-EV10 -> 0.33333333 | EV10: =SUM(ES10-ER10) -> 0 | EZ10: =FB10-مراجع!$B$2 -> -0.33333333 | FA10: =مراجع!$B$2-FB10 -> 0.33333333 | FB10: =SUM(EY10-EX10) -> 0 | FF10: =FH10-مراجع!$B$2 -> -0.33333333 | FG10: =مراجع!$B$2-FH10 -> 0.33333333 | FH10: =SUM(FE10-FD10) -> 0 | FL10: =FN10-مراجع!$B$2 -> -0.33333333 | FM10: =مراجع!$B$2-FN10 -> 0.33333333 | FN10: =SUM(FK10-FJ10) -> 0 | FR10: =FT10-مراجع!$B$2 -> -0.33333333 | FS10: =مراجع!$B$2-FT10 -> 0.33333333 | FT10: =SUM(FQ10-FP10) -> 0 | FX10: =FZ10-مراجع!$B$2 -> -0.33333333 | FY10: =مراجع!$B$2-FZ10 -> 0.33333333 | FZ10: =SUM(FW10-FV10) -> 0 | GD10: =GF10-مراجع!$B$2 -> -0.33333333 | GE10: =مراجع!$B$2-GF10 -> 0.33333333 | GF10: =SUM(GC10-GB10) -> 0
A11: مديحة حمدي | B11: محلل بيانات | C11: البنك الدولي | F11: =H11-مراجع!$B$2 -> -0.33333333 | G11: =مراجع!$B$2-H11 -> 0.33333333 | H11: =SUM(E11-D11) -> 0 | L11: =N11-مراجع!$B$2 -> -0.33333333 | M11: =مراجع!$B$2-N11 -> 0.33333333 | N11: =SUM(K11-J11) -> 0 | R11: =T11-مراجع!$B$2 -> -0.33333333 | S11: =مراجع!$B$2-T11 -> 0.33333333 | T11: =SUM(Q11-P11) -> 0 | X11: =Z11-مراجع!$B$2 -> -0.33333333 | Y11: =مراجع!$B$2-Z11 -> 0.33333333 | Z11: =SUM(W11-V11) -> 0 | AD11: =AF11-مراجع!$B$2 -> -0.33333333 | AE11: =مراجع!$B$2-AF11 -> 0.33333333 | AF11: =SUM(AC11-AB11) -> 0 | AJ11: =AL11-مراجع!$B$2 -> -0.33333333 | AK11: =مراجع!$B$2-AL11 -> 0.33333333 | AL11: =SUM(AI11-AH11) -> 0 | AP11: =AR11-مراجع!$B$2 -> -0.33333333 | AQ11: =مراجع!$B$2-AR11 -> 0.33333333 | AR11: =SUM(AO11-AN11) -> 0 | AV11: =AX11-مراجع!$B$2 -> -0.33333333 | AW11: =مراجع!$B$2-AX11 -> 0.33333333 | AX11: =SUM(AU11-AT11) -> 0 | BB11: =BD11-مراجع!$B$2 -> -0.33333333 | BC11: =مراجع!$B$2-BD11 -> 0.33333333 | BD11: =SUM(BA11-AZ11) -> 0 | BH11: =BJ11-مراجع!$B$2 -> -0.33333333 | BI11: =مراجع!$B$2-BJ11 -> 0.33333333 | BJ11: =SUM(BG11-BF11) -> 0 | BN11: =BP11-مراجع!$B$2 -> -0.33333333 | BO11: =مراجع!$B$2-BP11 -> 0.33333333 | BP11: =SUM(BM11-BL11) -> 0 | BT11: =BV11-مراجع!$B$2 -> -0.33333333 | BU11: =مراجع!$B$2-BV11 -> 0.33333333 | BV11: =SUM(BS11-BR11) -> 0 | BZ11: =CB11-مراجع!$B$2 -> -0.33333333 | CA11: =مراجع!$B$2-CB11 -> 0.33333333 | CB11: =SUM(BY11-BX11) -> 0 | CF11: =CH11-مراجع!$B$2 -> -0.33333333 | CG11: =مراجع!$B$2-CH11 -> 0.33333333 | CH11: =SUM(CE11-CD11) -> 0 | CL11: =CN11-مراجع!$B$2 -> -0.33333333 | CM11: =مراجع!$B$2-CN11 -> 0.33333333 | CN11: =SUM(CK11-CJ11) -> 0 | CR11: =CT11-مراجع!$B$2 -> -0.33333333 | CS11: =مراجع!$B$2-CT11 -> 0.33333333 | CT11: =SUM(CQ11-CP11) -> 0 | CX11: =CZ11-مراجع!$B$2 -> -0.33333333 | CY11: =مراجع!$B$2-CZ11 -> 0.33333333 | CZ11: =SUM(CW11-CV11) -> 0 | DD11: =DF11-مراجع!$B$2 -> -0.33333333 | DE11: =مراجع!$B$2-DF11 -> 0.33333333 | DF11: =SUM(DC11-DB11) -> 0 | DJ11: =DL11-مراجع!$B$2 -> -0.33333333 | DK11: =مراجع!$B$2-DL11 -> 0.33333333 | DL11: =SUM(DI11-DH11) -> 0 | DP11: =DR11-مراجع!$B$2 -> -0.33333333 | DQ11: =مراجع!$B$2-DR11 -> 0.33333333 | DR11: =SUM(DO11-DN11) -> 0 | DV11: =DX11-مراجع!$B$2 -> -0.33333333 | DW11: =مراجع!$B$2-DX11 -> 0.33333333 | DX11: =SUM(DU11-DT11) -> 0 | EB11: =ED11-مراجع!$B$2 -> -0.33333333 | EC11: =مراجع!$B$2-ED11 -> 0.33333333 | ED11: =SUM(EA11-DZ11) -> 0 | EH11: =EJ11-مراجع!$B$2 -> -0.33333333 | EI11: =مراجع!$B$2-EJ11 -> 0.33333333 | EJ11: =SUM(EG11-EF11) -> 0 | EN11: =EP11-مراجع!$B$2 -> -0.33333333 | EO11: =مراجع!$B$2-EP11 -> 0.33333333 | EP11: =SUM(EM11-EL11) -> 0 | ET11: =EV11-مراجع!$B$2 -> -0.33333333 | EU11: =مراجع!$B$2-EV11 -> 0.33333333 | EV11: =SUM(ES11-ER11) -> 0 | EZ11: =FB11-مراجع!$B$2 -> -0.33333333 | FA11: =مراجع!$B$2-FB11 -> 0.33333333 | FB11: =SUM(EY11-EX11) -> 0 | FF11: =FH11-مراجع!$B$2 -> -0.33333333 | FG11: =مراجع!$B$2-FH11 -> 0.33333333 | FH11: =SUM(FE11-FD11) -> 0 | FL11: =FN11-مراجع!$B$2 -> -0.33333333 | FM11: =مراجع!$B$2-FN11 -> 0.33333333 | FN11: =SUM(FK11-FJ11) -> 0 | FR11: =FT11-مراجع!$B$2 -> -0.33333333 | FS11: =مراجع!$B$2-FT11 -> 0.33333333 | FT11: =SUM(FQ11-FP11) -> 0 | FX11: =FZ11-مراجع!$B$2 -> -0.33333333 | FY11: =مراجع!$B$2-FZ11 -> 0.33333333 | FZ11: =SUM(FW11-FV11) -> 0 | GD11: =GF11-مراجع!$B$2 -> -0.33333333 | GE11: =مراجع!$B$2-GF11 -> 0.33333333 | GF11: =SUM(GC11-GB11) -> 0
A12: دينا سيد | B12: محلل بيانات | C12: البنك الدولي | F12: =H12-مراجع!$B$2 -> -0.33333333 | G12: =مراجع!$B$2-H12 -> 0.33333333 | H12: =SUM(E12-D12) -> 0 | L12: =N12-مراجع!$B$2 -> -0.33333333 | M12: =مراجع!$B$2-N12 -> 0.33333333 | N12: =SUM(K12-J12) -> 0 | R12: =T12-مراجع!$B$2 -> -0.33333333 | S12: =مراجع!$B$2-T12 -> 0.33333333 | T12: =SUM(Q12-P12) -> 0 | X12: =Z12-مراجع!$B$2 -> -0.33333333 | Y12: =مراجع!$B$2-Z12 -> 0.33333333 | Z12: =SUM(W12-V12) -> 0 | AD12: =AF12-مراجع!$B$2 -> -0.33333333 | AE12: =مراجع!$B$2-AF12 -> 0.33333333 | AF12: =SUM(AC12-AB12) -> 0 | AJ12: =AL12-مراجع!$B$2 -> -0.33333333 | AK12: =مراجع!$B$2-AL12 -> 0.33333333 | AL12: =SUM(AI12-AH12) -> 0 | AP12: =AR12-مراجع!$B$2 -> -0.33333333 | AQ12: =مراجع!$B$2-AR12 -> 0.33333333 | AR12: =SUM(AO12-AN12) -> 0 | AV12: =AX12-مراجع!$B$2 -> -0.33333333 | AW12: =مراجع!$B$2-AX12 -> 0.33333333 | AX12: =SUM(AU12-AT12) -> 0 | BB12: =BD12-مراجع!$B$2 -> -0.33333333 | BC12: =مراجع!$B$2-BD12 -> 0.33333333 | BD12: =SUM(BA12-AZ12) -> 0 | BH12: =BJ12-مراجع!$B$2 -> -0.33333333 | BI12: =مراجع!$B$2-BJ12 -> 0.33333333 | BJ12: =SUM(BG12-BF12) -> 0 | BN12: =BP12-مراجع!$B$2 -> -0.33333333 | BO12: =مراجع!$B$2-BP12 -> 0.33333333 | BP12: =SUM(BM12-BL12) -> 0 | BT12: =BV12-مراجع!$B$2 -> -0.33333333 | BU12: =مراجع!$B$2-BV12 -> 0.33333333 | BV12: =SUM(BS12-BR12) -> 0 | BZ12: =CB12-مراجع!$B$2 -> -0.33333333 | CA12: =مراجع!$B$2-CB12 -> 0.33333333 | CB12: =SUM(BY12-BX12) -> 0 | CF12: =CH12-مراجع!$B$2 -> -0.33333333 | CG12: =مراجع!$B$2-CH12 -> 0.33333333 | CH12: =SUM(CE12-CD12) -> 0 | CL12: =CN12-مراجع!$B$2 -> -0.33333333 | CM12: =مراجع!$B$2-CN12 -> 0.33333333 | CN12: =SUM(CK12-CJ12) -> 0 | CR12: =CT12-مراجع!$B$2 -> -0.33333333 | CS12: =مراجع!$B$2-CT12 -> 0.33333333 | CT12: =SUM(CQ12-CP12) -> 0 | CX12: =CZ12-مراجع!$B$2 -> -0.33333333 | CY12: =مراجع!$B$2-CZ12 -> 0.33333333 | CZ12: =SUM(CW12-CV12) -> 0 | DD12: =DF12-مراجع!$B$2 -> -0.33333333 | DE12: =مراجع!$B$2-DF12 -> 0.33333333 | DF12: =SUM(DC12-DB12) -> 0 | DJ12: =DL12-مراجع!$B$2 -> -0.33333333 | DK12: =مراجع!$B$2-DL12 -> 0.33333333 | DL12: =SUM(DI12-DH12) -> 0 | DP12: =DR12-مراجع!$B$2 -> -0.33333333 | DQ12: =مراجع!$B$2-DR12 -> 0.33333333 | DR12: =SUM(DO12-DN12) -> 0 | DV12: =DX12-مراجع!$B$2 -> -0.33333333 | DW12: =مراجع!$B$2-DX12 -> 0.33333333 | DX12: =SUM(DU12-DT12) -> 0 | EB12: =ED12-مراجع!$B$2 -> -0.33333333 | EC12: =مراجع!$B$2-ED12 -> 0.33333333 | ED12: =SUM(EA12-DZ12) -> 0 | EH12: =EJ12-مراجع!$B$2 -> -0.33333333 | EI12: =مراجع!$B$2-EJ12 -> 0.33333333 | EJ12: =SUM(EG12-EF12) -> 0 | EN12: =EP12-مراجع!$B$2 -> -0.33333333 | EO12: =مراجع!$B$2-EP12 -> 0.33333333 | EP12: =SUM(EM12-EL12) -> 0 | ET12: =EV12-مراجع!$B$2 -> -0.33333333 | EU12: =مراجع!$B$2-EV12 -> 0.33333333 | EV12: =SUM(ES12-ER12) -> 0 | EZ12: =FB12-مراجع!$B$2 -> -0.33333333 | FA12: =مراجع!$B$2-FB12 -> 0.33333333 | FB12: =SUM(EY12-EX12) -> 0 | FF12: =FH12-مراجع!$B$2 -> -0.33333333 | FG12: =مراجع!$B$2-FH12 -> 0.33333333 | FH12: =SUM(FE12-FD12) -> 0 | FL12: =FN12-مراجع!$B$2 -> -0.33333333 | FM12: =مراجع!$B$2-FN12 -> 0.33333333 | FN12: =SUM(FK12-FJ12) -> 0 | FR12: =FT12-مراجع!$B$2 -> -0.33333333 | FS12: =مراجع!$B$2-FT12 -> 0.33333333 | FT12: =SUM(FQ12-FP12) -> 0 | FX12: =FZ12-مراجع!$B$2 -> -0.33333333 | FY12: =مراجع!$B$2-FZ12 -> 0.33333333 | FZ12: =SUM(FW12-FV12) -> 0 | GD12: =GF12-مراجع!$B$2 -> -0.33333333 | GE12: =مراجع!$B$2-GF12 -> 0.33333333 | GF12: =SUM(GC12-GB12) -> 0
A13: أحمد نبوي | B13: خدمات معاونة | C13: القرض الفرنسي | F13: =H13-مراجع!$B$2 -> -0.33333333 | G13: =مراجع!$B$2-H13 -> 0.33333333 | H13: =SUM(E13-D13) -> 0 | L13: =N13-مراجع!$B$2 -> -0.33333333 | M13: =مراجع!$B$2-N13 -> 0.33333333 | N13: =SUM(K13-J13) -> 0 | R13: =T13-مراجع!$B$2 -> -0.33333333 | S13: =مراجع!$B$2-T13 -> 0.33333333 | T13: =SUM(Q13-P13) -> 0 | X13: =Z13-مراجع!$B$2 -> -0.33333333 | Y13: =مراجع!$B$2-Z13 -> 0.33333333 | Z13: =SUM(W13-V13) -> 0 | AD13: =AF13-مراجع!$B$2 -> -0.33333333 | AE13: =مراجع!$B$2-AF13 -> 0.33333333 | AF13: =SUM(AC13-AB13) -> 0 | AJ13: =AL13-مراجع!$B$2 -> -0.33333333 | AK13: =مراجع!$B$2-AL13 -> 0.33333333 | AL13: =SUM(AI13-AH13) -> 0 | AP13: =AR13-مراجع!$B$2 -> -0.33333333 | AQ13: =مراجع!$B$2-AR13 -> 0.33333333 | AR13: =SUM(AO13-AN13) -> 0 | AV13: =AX13-مراجع!$B$2 -> -0.33333333 | AW13: =مراجع!$B$2-AX13 -> 0.33333333 | AX13: =SUM(AU13-AT13) -> 0 | BB13: =BD13-مراجع!$B$2 -> -0.33333333 | BC13: =مراجع!$B$2-BD13 -> 0.33333333 | BD13: =SUM(BA13-AZ13) -> 0 | BH13: =BJ13-مراجع!$B$2 -> -0.33333333 | BI13: =مراجع!$B$2-BJ13 -> 0.33333333 | BJ13: =SUM(BG13-BF13) -> 0 | BN13: =BP13-مراجع!$B$2 -> -0.33333333 | BO13: =مراجع!$B$2-BP13 -> 0.33333333 | BP13: =SUM(BM13-BL13) -> 0 | BT13: =BV13-مراجع!$B$2 -> -0.33333333 | BU13: =مراجع!$B$2-BV13 -> 0.33333333 | BV13: =SUM(BS13-BR13) -> 0 | BZ13: =CB13-مراجع!$B$2 -> -0.33333333 | CA13: =مراجع!$B$2-CB13 -> 0.33333333 | CB13: =SUM(BY13-BX13) -> 0 | CF13: =CH13-مراجع!$B$2 -> -0.33333333 | CG13: =مراجع!$B$2-CH13 -> 0.33333333 | CH13: =SUM(CE13-CD13) -> 0 | CL13: =CN13-مراجع!$B$2 -> -0.33333333 | CM13: =مراجع!$B$2-CN13 -> 0.33333333 | CN13: =SUM(CK13-CJ13) -> 0 | CR13: =CT13-مراجع!$B$2 -> -0.33333333 | CS13: =مراجع!$B$2-CT13 -> 0.33333333 | CT13: =SUM(CQ13-CP13) -> 0 | CX13: =CZ13-مراجع!$B$2 -> -0.33333333 | CY13: =مراجع!$B$2-CZ13 -> 0.33333333 | CZ13: =SUM(CW13-CV13) -> 0 | DD13: =DF13-مراجع!$B$2 -> -0.33333333 | DE13: =مراجع!$B$2-DF13 -> 0.33333333 | DF13: =SUM(DC13-DB13) -> 0 | DJ13: =DL13-مراجع!$B$2 -> -0.33333333 | DK13: =مراجع!$B$2-DL13 -> 0.33333333 | DL13: =SUM(DI13-DH13) -> 0 | DP13: =DR13-مراجع!$B$2 -> -0.33333333 | DQ13: =مراجع!$B$2-DR13 -> 0.33333333 | DR13: =SUM(DO13-DN13) -> 0 | DV13: =DX13-مراجع!$B$2 -> -0.33333333 | DW13: =مراجع!$B$2-DX13 -> 0.33333333 | DX13: =SUM(DU13-DT13) -> 0 | EB13: =ED13-مراجع!$B$2 -> -0.33333333 | EC13: =مراجع!$B$2-ED13 -> 0.33333333 | ED13: =SUM(EA13-DZ13) -> 0 | EH13: =EJ13-مراجع!$B$2 -> -0.33333333 | EI13: =مراجع!$B$2-EJ13 -> 0.33333333 | EJ13: =SUM(EG13-EF13) -> 0 | EN13: =EP13-مراجع!$B$2 -> -0.33333333 | EO13: =مراجع!$B$2-EP13 -> 0.33333333 | EP13: =SUM(EM13-EL13) -> 0 | ET13: =EV13-مراجع!$B$2 -> -0.33333333 | EU13: =مراجع!$B$2-EV13 -> 0.33333333 | EV13: =SUM(ES13-ER13) -> 0 | EZ13: =FB13-مراجع!$B$2 -> -0.33333333 | FA13: =مراجع!$B$2-FB13 -> 0.33333333 | FB13: =SUM(EY13-EX13) -> 0 | FF13: =FH13-مراجع!$B$2 -> -0.33333333 | FG13: =مراجع!$B$2-FH13 -> 0.33333333 | FH13: =SUM(FE13-FD13) -> 0 | FL13: =FN13-مراجع!$B$2 -> -0.33333333 | FM13: =مراجع!$B$2-FN13 -> 0.33333333 | FN13: =SUM(FK13-FJ13) -> 0 | FR13: =FT13-مراجع!$B$2 -> -0.33333333 | FS13: =مراجع!$B$2-FT13 -> 0.33333333 | FT13: =SUM(FQ13-FP13) -> 0 | FX13: =FZ13-مراجع!$B$2 -> -0.33333333 | FY13: =مراجع!$B$2-FZ13 -> 0.33333333 | FZ13: =SUM(FW13-FV13) -> 0 | GD13: =GF13-مراجع!$B$2 -> -0.33333333 | GE13: =مراجع!$B$2-GF13 -> 0.33333333 | GF13: =SUM(GC13-GB13) -> 0
A14: محمد إبراهيم | B14: خدمات معاونة | C14: القرض الفرنسي | F14: =H14-مراجع!$B$2 -> -0.33333333 | G14: =مراجع!$B$2-H14 -> 0.33333333 | H14: =SUM(E14-D14) -> 0 | L14: =N14-مراجع!$B$2 -> -0.33333333 | M14: =مراجع!$B$2-N14 -> 0.33333333 | N14: =SUM(K14-J14) -> 0 | R14: =T14-مراجع!$B$2 -> -0.33333333 | S14: =مراجع!$B$2-T14 -> 0.33333333 | T14: =SUM(Q14-P14) -> 0 | X14: =Z14-مراجع!$B$2 -> -0.33333333 | Y14: =مراجع!$B$2-Z14 -> 0.33333333 | Z14: =SUM(W14-V14) -> 0 | AD14: =AF14-مراجع!$B$2 -> -0.33333333 | AE14: =مراجع!$B$2-AF14 -> 0.33333333 | AF14: =SUM(AC14-AB14) -> 0 | AJ14: =AL14-مراجع!$B$2 -> -0.33333333 | AK14: =مراجع!$B$2-AL14 -> 0.33333333 | AL14: =SUM(AI14-AH14) -> 0 | AP14: =AR14-مراجع!$B$2 -> -0.33333333 | AQ14: =مراجع!$B$2-AR14 -> 0.33333333 | AR14: =SUM(AO14-AN14) -> 0 | AV14: =AX14-مراجع!$B$2 -> -0.33333333 | AW14: =مراجع!$B$2-AX14 -> 0.33333333 | AX14: =SUM(AU14-AT14) -> 0 | BB14: =BD14-مراجع!$B$2 -> -0.33333333 | BC14: =مراجع!$B$2-BD14 -> 0.33333333 | BD14: =SUM(BA14-AZ14) -> 0 | BH14: =BJ14-مراجع!$B$2 -> -0.33333333 | BI14: =مراجع!$B$2-BJ14 -> 0.33333333 | BJ14: =SUM(BG14-BF14) -> 0 | BN14: =BP14-مراجع!$B$2 -> -0.33333333 | BO14: =مراجع!$B$2-BP14 -> 0.33333333 | BP14: =SUM(BM14-BL14) -> 0 | BT14: =BV14-مراجع!$B$2 -> -0.33333333 | BU14: =مراجع!$B$2-BV14 -> 0.33333333 | BV14: =SUM(BS14-BR14) -> 0 | BZ14: =CB14-مراجع!$B$2 -> -0.33333333 | CA14: =مراجع!$B$2-CB14 -> 0.33333333 | CB14: =SUM(BY14-BX14) -> 0 | CF14: =CH14-مراجع!$B$2 -> -0.33333333 | CG14: =مراجع!$B$2-CH14 -> 0.33333333 | CH14: =SUM(CE14-CD14) -> 0 | CL14: =CN14-مراجع!$B$2 -> -0.33333333 | CM14: =مراجع!$B$2-CN14 -> 0.33333333 | CN14: =SUM(CK14-CJ14) -> 0 | CR14: =CT14-مراجع!$B$2 -> -0.33333333 | CS14: =مراجع!$B$2-CT14 -> 0.33333333 | CT14: =SUM(CQ14-CP14) -> 0 | CX14: =CZ14-مراجع!$B$2 -> -0.33333333 | CY14: =مراجع!$B$2-CZ14 -> 0.33333333 | CZ14: =SUM(CW14-CV14) -> 0 | DD14: =DF14-مراجع!$B$2 -> -0.33333333 | DE14: =مراجع!$B$2-DF14 -> 0.33333333 | DF14: =SUM(DC14-DB14) -> 0 | DJ14: =DL14-مراجع!$B$2 -> -0.33333333 | DK14: =مراجع!$B$2-DL14 -> 0.33333333 | DL14: =SUM(DI14-DH14) -> 0 | DP14: =DR14-مراجع!$B$2 -> -0.33333333 | DQ14: =مراجع!$B$2-DR14 -> 0.33333333 | DR14: =SUM(DO14-DN14) -> 0 | DV14: =DX14-مراجع!$B$2 -> -0.33333333 | DW14: =مراجع!$B$2-DX14 -> 0.33333333 | DX14: =SUM(DU14-DT14) -> 0 | EB14: =ED14-مراجع!$B$2 -> -0.33333333 | EC14: =مراجع!$B$2-ED14 -> 0.33333333 | ED14: =SUM(EA14-DZ14) -> 0 | EH14: =EJ14-مراجع!$B$2 -> -0.33333333 | EI14: =مراجع!$B$2-EJ14 -> 0.33333333 | EJ14: =SUM(EG14-EF14) -> 0 | EN14: =EP14-مراجع!$B$2 -> -0.33333333 | EO14: =مراجع!$B$2-EP14 -> 0.33333333 | EP14: =SUM(EM14-EL14) -> 0 | ET14: =EV14-مراجع!$B$2 -> -0.33333333 | EU14: =مراجع!$B$2-EV14 -> 0.33333333 | EV14: =SUM(ES14-ER14) -> 0 | EZ14: =FB14-مراجع!$B$2 -> -0.33333333 | FA14: =مراجع!$B$2-FB14 -> 0.33333333 | FB14: =SUM(EY14-EX14) -> 0 | FF14: =FH14-مراجع!$B$2 -> -0.33333333 | FG14: =مراجع!$B$2-FH14 -> 0.33333333 | FH14: =SUM(FE14-FD14) -> 0 | FL14: =FN14-مراجع!$B$2 -> -0.33333333 | FM14: =مراجع!$B$2-FN14 -> 0.33333333 | FN14: =SUM(FK14-FJ14) -> 0 | FR14: =FT14-مراجع!$B$2 -> -0.33333333 | FS14: =مراجع!$B$2-FT14 -> 0.33333333 | FT14: =SUM(FQ14-FP14) -> 0 | FX14: =FZ14-مراجع!$B$2 -> -0.33333333 | FY14: =مراجع!$B$2-FZ14 -> 0.33333333 | FZ14: =SUM(FW14-FV14) -> 0 | GD14: =GF14-مراجع!$B$2 -> -0.33333333 | GE14: =مراجع!$B$2-GF14 -> 0.33333333 | GF14: =SUM(GC14-GB14) -> 0

Sheet تقرير حضور مجمع
B1: إسم المشروع | G1: - | J1: الموقع | M1: وزارة الصحة | P1: -
B2: الشهر | G2: يناير | J2: السنة | P2: -
B3: RـــEـــPـــOـــRـــT
B4: مسلسل | C4: بيانات | F4: إجمالي | J4: غيابات | M4: رصيد إجازات | O4: إجازات رسمية | P4: حضور
B5: الرقم | C5: الإسم | D5: الوظيفة | E5: المشروع | F5: ساعات الحضور | G5: إضافي | H5: خصم | I5: أيام الحضور | J5: عارضة | K5: إعتيادي | L5: بدون إذن | M5: عارضة | N5: إعتيادي | P5: الجمعة | Q5: السبت | R5: مأمورية
B6: 1 | C6: كريم محمود | D6: سكرتير | E6: البنك الدولي | F6: =SUM('كـشـف حضور يومي'!H4,'كـشـف حضور يومي'!N4,'كـشـف حضور يومي'!T4,'كـشـف حضور يومي'!Z4,'كـشـف حضور يومي'!AF4,'كـشـف حضور يومي'!AL4,'كـشـف حضور يومي'!AR4,'كـشـف حضور يومي'!AX4,'كـشـف حضور يومي'!BD4,'كـشـف حضور يومي'!BJ4,'كـشـف حضور يومي'!BP4,'كـشـف حضور يومي'!BV4,'كـشـف حضور يومي'!CB4,'كـشـف حضور يومي'!CH4,'كـشـف حضور يومي'!CN4,'كـشـف حضور يومي'!CT4,'كـشـف حضور يومي'!CZ4,'كـشـف حضور يومي'!DF4,'كـشـف حضور يومي'!DL4,'كـشـف حضور يومي'!DR4,'كـشـف حضور يومي'!DX4,'كـشـف حضور يومي'!ED4,'كـشـف حضور يومي'!EJ4,'كـشـف حضور يومي'!EP4,'كـشـف حضور يومي'!EV4,'كـشـف حضور يومي'!FB4,'كـشـف حضور يومي'!FH4,'كـشـف حضور يومي'!FN4,'كـشـف حضور يومي'!FT4,'كـشـف حضور يومي'!FZ4,'كـشـف حضور يومي'!GF4) -> 8.3333333 | G6: =F6-مراجع!$A$2 -> -0.33333333 | H6: =مراجع!$A$2-F6 -> 0.33333333 | I6: =COUNTIFS('كـشـف حضور يومي'!D4:GG4, "*حضور*") -> 0 | J6: =COUNTIF('كـشـف حضور يومي'!D4:GG4,مراجع!$D$3) -> 0 | K6: =COUNTIF('كـشـف حضور يومي'!D4:GG4,مراجع!$E$3) -> 0 | L6: =COUNTIF('كـشـف حضور يومي'!D4:GG4,مراجع!$K$3) -> 0 | M6: =مراجع!$C$2-J6 -> 7 | N6: =مراجع!$D$2-K6 -> 21 | O6: =COUNTIF('كـشـف حضور يومي'!D4:GG4,مراجع!$F$3) -> 0 | P6: =COUNTIFS('كـشـف حضور يومي'!D4:GG4, "*الجمعة*") -> 0 | Q6: =COUNTIFS('كـشـف حضور يومي'!D4:GG4, "*السبت*") -> 0 | R6: =COUNTIFS('كـشـف حضور يومي'!D4:GG4, "*مأمورية*") -> 0
B7: 2 | C7: عبد العزيز محمد | D7: محلل بيانات | E7: البنك الدولي | F7: =SUM('كـشـف حضور يومي'!H5,'كـشـف حضور يومي'!N5,'كـشـف حضور يومي'!T5,'كـشـف حضور يومي'!Z5,'كـشـف حضور يومي'!AF5,'كـشـف حضور يومي'!AL5,'كـشـف حضور يومي'!AR5,'كـشـف حضور يومي'!AX5,'كـشـف حضور يومي'!BD5,'كـشـف حضور يومي'!BJ5,'كـشـف حضور يومي'!BP5,'كـشـف حضور يومي'!BV5,'كـشـف حضور يومي'!CB5,'كـشـف حضور يومي'!CH5,'كـشـف حضور يومي'!CN5,'كـشـف حضور يومي'!CT5,'كـشـف حضور يومي'!CZ5,'كـشـف حضور يومي'!DF5,'كـشـف حضور يومي'!DL5,'كـشـف حضور يومي'!DR5,'كـشـف حضور يومي'!DX5,'كـشـف حضور يومي'!ED5,'كـشـف حضور يومي'!EJ5,'كـشـف حضور يومي'!EP5,'كـشـف حضور يومي'!EV5,'كـشـف حضور يومي'!FB5,'كـشـف حضور يومي'!FH5,'كـشـف حضور يومي'!FN5,'كـشـف حضور يومي'!FT5,'كـشـف حضور يومي'!FZ5,'كـشـف حضور يومي'!GF5) -> 0 | G7: =F7-مراجع!$A$2 -> -8.6666667 | H7: =مراجع!$A$2-F7 -> 8.6666667 | I7: =COUNTIFS('كـشـف حضور يومي'!D5:GG5, "*حضور*") -> 0 | J7: =COUNTIF('كـشـف حضور يومي'!D5:GG5,$J$5) -> 0 | K7: =COUNTIF('كـشـف حضور يومي'!D5:GG5,مراجع!$E$3) -> 0 | L7: =COUNTIF('كـشـف حضور يومي'!D5:GG5,مراجع!$K$3) -> 0 | M7: =مراجع!$C$2-J7 -> 7 | N7: =مراجع!$D$2-K7 -> 21 | O7: =COUNTIF('كـشـف حضور يومي'!D5:GG5,مراجع!$F$3) -> 0 | P7: =COUNTIFS('كـشـف حضور يومي'!D5:GG5, "*الجمعة*") -> 0 | Q7: =COUNTIFS('كـشـف حضور يومي'!D5:GG5, "*السبت*") -> 0 | R7: =COUNTIFS('كـشـف حضور يومي'!D5:GG5, "*مأمورية*") -> 0
B8: 3 | C8: محمد حسين | D8: محاسب | E8: البنك الدولي | F8: =SUM('كـشـف حضور يومي'!H6,'كـشـف حضور يومي'!N6,'كـشـف حضور يومي'!T6,'كـشـف حضور يومي'!Z6,'كـشـف حضور يومي'!AF6,'كـشـف حضور يومي'!AL6,'كـشـف حضور يومي'!AR6,'كـشـف حضور يومي'!AX6,'كـشـف حضور يومي'!BD6,'كـشـف حضور يومي'!BJ6,'كـشـف حضور يومي'!BP6,'كـشـف حضور يومي'!BV6,'كـشـف حضور يومي'!CB6,'كـشـف حضور يومي'!CH6,'كـشـف حضور يومي'!CN6,'كـشـف حضور يومي'!CT6,'كـشـف حضور يومي'!CZ6,'كـشـف حضور يومي'!DF6,'كـشـف حضور يومي'!DL6,'كـشـف حضور يومي'!DR6,'كـشـف حضور يومي'!DX6,'كـشـف حضور يومي'!ED6,'كـشـف حضور يومي'!EJ6,'كـشـف حضور يومي'!EP6,'كـشـف حضور يومي'!EV6,'كـشـف حضور يومي'!FB6,'كـشـف حضور يومي'!FH6,'كـشـف حضور يومي'!FN6,'كـشـف حضور يومي'!FT6,'كـشـف حضور يومي'!FZ6,'كـشـف حضور يومي'!GF6) -> 0 | G8: =F8-مراجع!$A$2 -> -8.6666667 | H8: =مراجع!$A$2-F8 -> 8.6666667 | I8: =COUNTIFS('كـشـف حضور يومي'!D6:GG6, "*حضور*") -> 0 | J8: =COUNTIF('كـشـف حضور يومي'!D6:GG6,$J$5) -> 0 | K8: =COUNTIF('كـشـف حضور يومي'!D6:GG6,مراجع!$E$3) -> 0 | L8: =COUNTIF('كـشـف حضور يومي'!D6:GG6,مراجع!$K$3) -> 0 | M8: =مراجع!$C$2-J8 -> 7 | N8: =مراجع!$D$2-K8 -> 21 | O8: =COUNTIF('كـشـف حضور يومي'!D6:GG6,مراجع!$F$3) -> 0 | P8: =COUNTIFS('كـشـف حضور يومي'!D6:GG6, "*الجمعة*") -> 0 | Q8: =COUNTIFS('كـشـف حضور يومي'!D6:GG6, "*السبت*") -> 0 | R8: =COUNTIFS('كـشـف حضور يومي'!D6:GG6, "*مأمورية*") -> 0
B9: 4 | C9: هالة محمود | D9: مسئول قواعد بيانات | E9: القرض الفرنسي | F9: =SUM('كـشـف حضور يومي'!H7,'كـشـف حضور يومي'!N7,'كـشـف حضور يومي'!T7,'كـشـف حضور يومي'!Z7,'كـشـف حضور يومي'!AF7,'كـشـف حضور يومي'!AL7,'كـشـف حضور يومي'!AR7,'كـشـف حضور يومي'!AX7,'كـشـف حضور يومي'!BD7,'كـشـف حضور يومي'!BJ7,'كـشـف حضور يومي'!BP7,'كـشـف حضور يومي'!BV7,'كـشـف حضور يومي'!CB7,'كـشـف حضور يومي'!CH7,'كـشـف حضور يومي'!CN7,'كـشـف حضور يومي'!CT7,'كـشـف حضور يومي'!CZ7,'كـشـف حضور يومي'!DF7,'كـشـف حضور يومي'!DL7,'كـشـف حضور يومي'!DR7,'كـشـف حضور يومي'!DX7,'كـشـف حضور يومي'!ED7,'كـشـف حضور يومي'!EJ7,'كـشـف حضور يومي'!EP7,'كـشـف حضور يومي'!EV7,'كـشـف حضور يومي'!FB7,'كـشـف حضور يومي'!FH7,'كـشـف حضور يومي'!FN7,'كـشـف حضور يومي'!FT7,'كـشـف حضور يومي'!FZ7,'كـشـف حضور يومي'!GF7) -> 0 | G9: =F9-مراجع!$A$2 -> -8.6666667 | H9: =مراجع!$A$2-F9 -> 8.6666667 | I9: =COUNTIFS('كـشـف حضور يومي'!D7:GG7, "*حضور*") -> 0 | J9: =COUNTIF('كـشـف حضور يومي'!D7:GG7,$J$5) -> 0 | K9: =COUNTIF('كـشـف حضور يومي'!D7:GG7,مراجع!$E$3) -> 0 | L9: =COUNTIF('كـشـف حضور يومي'!D7:GG7,مراجع!$K$3) -> 0 | M9: =مراجع!$C$2-J9 -> 7 | N9: =مراجع!$D$2-K9 -> 21 | O9: =COUNTIF('كـشـف حضور يومي'!D7:GG7,مراجع!$F$3) -> 0 | P9: =COUNTIFS('كـشـف حضور يومي'!D7:GG7, "*الجمعة*") -> 0 | Q9: =COUNTIFS('كـشـف حضور يومي'!D7:GG7, "*السبت*") -> 0 | R9: =COUNTIFS('كـشـف حضور يومي'!D7:GG7, "*مأمورية*") -> 0
B10: 5 | C10: إسلام محمد | D10: منسق مشروع | E10: البنك الدولي | F10: =SUM('كـشـف حضور يومي'!H8,'كـشـف حضور يومي'!N8,'كـشـف حضور يومي'!T8,'كـشـف حضور يومي'!Z8,'كـشـف حضور يومي'!AF8,'كـشـف حضور يومي'!AL8,'كـشـف حضور يومي'!AR8,'كـشـف حضور يومي'!AX8,'كـشـف حضور يومي'!BD8,'كـشـف حضور يومي'!BJ8,'كـشـف حضور يومي'!BP8,'كـشـف حضور يومي'!BV8,'كـشـف حضور يومي'!CB8,'كـشـف حضور يومي'!CH8,'كـشـف حضور يومي'!CN8,'كـشـف حضور يومي'!CT8,'كـشـف حضور يومي'!CZ8,'كـشـف حضور يومي'!DF8,'كـشـف حضور يومي'!DL8,'كـشـف حضور يومي'!DR8,'كـشـف حضور يومي'!DX8,'كـشـف حضور يومي'!ED8,'كـشـف حضور يومي'!EJ8,'كـشـف حضور يومي'!EP8,'كـشـف حضور يومي'!EV8,'كـشـف حضور يومي'!FB8,'كـشـف حضور يومي'!FH8,'كـشـف حضور يومي'!FN8,'كـشـف حضور يومي'!FT8,'كـشـف حضور يومي'!FZ8,'كـشـف حضور يومي'!GF8) -> 0 | G10: =F10-مراجع!$A$2 -> -8.6666667 | H10: =مراجع!$A$2-F10 -> 8.6666667 | I10: =COUNTIFS('كـشـف حضور يومي'!D8:GG8, "*حضور*") -> 0 | J10: =COUNTIF('كـشـف حضور يومي'!D8:GG8,$J$5) -> 0 | K10: =COUNTIF('كـشـف حضور يومي'!D8:GG8,مراجع!$E$3) -> 0 | L10: =COUNTIF('كـشـف حضور يومي'!D8:GG8,مراجع!$K$3) -> 0 | M10: =مراجع!$C$2-J10 -> 7 | N10: =مراجع!$D$2-K10 -> 21 | O10: =COUNTIF('كـشـف حضور يومي'!D8:GG8,مراجع!$F$3) -> 0 | P10: =COUNTIFS('كـشـف حضور يومي'!D8:GG8, "*الجمعة*") -> 0 | Q10: =COUNTIFS('كـشـف حضور يومي'!D8:GG8, "*السبت*") -> 0 | R10: =COUNTIFS('كـشـف حضور يومي'!D8:GG8, "*مأمورية*") -> 0
B11: 6 | C11: أحمد عبد المنعم | D11: محاسب | E11: البنك الدولي | F11: =SUM('كـشـف حضور يومي'!H9,'كـشـف حضور يومي'!N9,'كـشـف حضور يومي'!T9,'كـشـف حضور يومي'!Z9,'كـشـف حضور يومي'!AF9,'كـشـف حضور يومي'!AL9,'كـشـف حضور يومي'!AR9,'كـشـف حضور يومي'!AX9,'كـشـف حضور يومي'!BD9,'كـشـف حضور يومي'!BJ9,'كـشـف حضور يومي'!BP9,'كـشـف حضور يومي'!BV9,'كـشـف حضور يومي'!CB9,'كـشـف حضور يومي'!CH9,'كـشـف حضور يومي'!CN9,'كـشـف حضور يومي'!CT9,'كـشـف حضور يومي'!CZ9,'كـشـف حضور يومي'!DF9,'كـشـف حضور يومي'!DL9,'كـشـف حضور يومي'!DR9,'كـشـف حضور يومي'!DX9,'كـشـف حضور يومي'!ED9,'كـشـف حضور يومي'!EJ9,'كـشـف حضور يومي'!EP9,'كـشـف حضور يومي'!EV9,'كـشـف حضور يومي'!FB9,'كـشـف حضور يومي'!FH9,'كـشـف حضور يومي'!FN9,'كـشـف حضور يومي'!FT9,'كـشـف حضور يومي'!FZ9,'كـشـف حضور يومي'!GF9) -> 0 | G11: =F11-مراجع!$A$2 -> -8.6666667 | H11: =مراجع!$A$2-F11 -> 8.6666667 | I11: =COUNTIFS('كـشـف حضور يومي'!D9:GG9, "*حضور*") -> 0 | J11: =COUNTIF('كـشـف حضور يومي'!D9:GG9,$J$5) -> 0 | K11: =COUNTIF('كـشـف حضور يومي'!D9:GG9,مراجع!$E$3) -> 0 | L11: =COUNTIF('كـشـف حضور يومي'!D9:GG9,مراجع!$K$3) -> 0 | M11: =مراجع!$C$2-J11 -> 7 | N11: =مراجع!$D$2-K11 -> 21 | O11: =COUNTIF('كـشـف حضور يومي'!D9:GG9,مراجع!$F$3) -> 0 | P11: =COUNTIFS('كـشـف حضور يومي'!D9:GG9, "*الجمعة*") -> 0 | Q11: =COUNTIFS('كـشـف حضور يومي'!D9:GG9, "*السبت*") -> 0 | R11: =COUNTIFS('كـشـف حضور يومي'!D9:GG9, "*مأمورية*") -> 0
B12: 7 | C12: هاجر أحمد | D12: مسئول قواعد بيانات | E12: القرض الفرنسي | F12: =SUM('كـشـف حضور يومي'!H10,'كـشـف حضور يومي'!N10,'كـشـف حضور يومي'!T10,'كـشـف حضور يومي'!Z10,'كـشـف حضور يومي'!AF10,'كـشـف حضور يومي'!AL10,'كـشـف حضور يومي'!AR10,'كـشـف حضور يومي'!AX10,'كـشـف حضور يومي'!BD10,'كـشـف حضور يومي'!BJ10,'كـشـف حضور يومي'!BP10,'كـشـف حضور يومي'!BV10,'كـشـف حضور يومي'!CB10,'كـشـف حضور يومي'!CH10,'كـشـف حضور يومي'!CN10,'كـشـف حضور يومي'!CT10,'كـشـف حضور يومي'!CZ10,'كـشـف حضور يومي'!DF10,'كـشـف حضور يومي'!DL10,'كـشـف حضور يومي'!DR10,'كـشـف حضور يومي'!DX10,'كـشـف حضور يومي'!ED10,'كـشـف حضور يومي'!EJ10,'كـشـف حضور يومي'!EP10,'كـشـف حضور يومي'!EV10,'كـشـف حضور يومي'!FB10,'كـشـف حضور يومي'!FH10,'كـشـف حضور يومي'!FN10,'كـشـف حضور يومي'!FT10,'كـشـف حضور يومي'!FZ10,'كـشـف حضور يومي'!GF10) -> 0 | G12: =F12-مراجع!$A$2 -> -8.6666667 | H12: =مراجع!$A$2-F12 -> 8.6666667 | I12: =COUNTIFS('كـشـف حضور يومي'!D10:GG10, "*حضور*") -> 0 | J12: =COUNTIF('كـشـف حضور يومي'!D10:GG10,$J$5) -> 0 | K12: =COUNTIF('كـشـف حضور يومي'!D10:GG10,مراجع!$E$3) -> 0 | L12: =COUNTIF('كـشـف حضور يومي'!D10:GG10,مراجع!$K$3) -> 0 | M12: =مراجع!$C$2-J12 -> 7 | N12: =مراجع!$D$2-K12 -> 21 | O12: =COUNTIF('كـشـف حضور يومي'!D10:GG10,مراجع!$F$3) -> 0 | P12: =COUNTIFS('كـشـف حضور يومي'!D10:GG10, "*الجمعة*") -> 0 | Q12: =COUNTIFS('كـشـف حضور يومي'!D10:GG10, "*السبت*") -> 0 | R12: =COUNTIFS('كـشـف حضور يومي'!D10:GG10, "*مأمورية*") -> 0
B13: 8 | C13: مديحة حمدي | D13: محلل بيانات | E13: البنك الدولي | F13: =SUM('كـشـف حضور يومي'!H11,'كـشـف حضور يومي'!N11,'كـشـف حضور يومي'!T11,'كـشـف حضور يومي'!Z11,'كـشـف حضور يومي'!AF11,'كـشـف حضور يومي'!AL11,'كـشـف حضور يومي'!AR11,'كـشـف حضور يومي'!AX11,'كـشـف حضور يومي'!BD11,'كـشـف حضور يومي'!BJ11,'كـشـف حضور يومي'!BP11,'كـشـف حضور يومي'!BV11,'كـشـف حضور يومي'!CB11,'كـشـف حضور يومي'!CH11,'كـشـف حضور يومي'!CN11,'كـشـف حضور يومي'!CT11,'كـشـف حضور يومي'!CZ11,'كـشـف حضور يومي'!DF11,'كـشـف حضور يومي'!DL11,'كـشـف حضور يومي'!DR11,'كـشـف حضور يومي'!DX11,'كـشـف حضور يومي'!ED11,'كـشـف حضور يومي'!EJ11,'كـشـف حضور يومي'!EP11,'كـشـف حضور يومي'!EV11,'كـشـف حضور يومي'!FB11,'كـشـف حضور يومي'!FH11,'كـشـف حضور يومي'!FN11,'كـشـف حضور يومي'!FT11,'كـشـف حضور يومي'!FZ11,'كـشـف حضور يومي'!GF11) -> 0 | G13: =F13-مراجع!$A$2 -> -8.6666667 | H13: =مراجع!$A$2-F13 -> 8.6666667 | I13: =COUNTIFS('كـشـف حضور يومي'!D11:GG11, "*حضور*") -> 0 | J13: =COUNTIF('كـشـف حضور يومي'!D11:GG11,$J$5) -> 0 | K13: =COUNTIF('كـشـف حضور يومي'!D11:GG11,مراجع!$E$3) -> 0 | L13: =COUNTIF('كـشـف حضور يومي'!D11:GG11,مراجع!$K$3) -> 0 | M13: =مراجع!$C$2-J13 -> 7 | N13: =مراجع!$D$2-K13 -> 21 | O13: =COUNTIF('كـشـف حضور يومي'!D11:GG11,مراجع!$F$3) -> 0 | P13: =COUNTIFS('كـشـف حضور يومي'!D11:GG11, "*الجمعة*") -> 0 | Q13: =COUNTIFS('كـشـف حضور يومي'!D11:GG11, "*السبت*") -> 0 | R13: =COUNTIFS('كـشـف حضور يومي'!D11:GG11, "*مأمورية*") -> 0
B14: 10 | C14: دينا سيد | D14: محلل بيانات | E14: البنك الدولي | F14: =SUM('كـشـف حضور يومي'!H12,'كـشـف حضور يومي'!N12,'كـشـف حضور يومي'!T12,'كـشـف حضور يومي'!Z12,'كـشـف حضور يومي'!AF12,'كـشـف حضور يومي'!AL12,'كـشـف حضور يومي'!AR12,'كـشـف حضور يومي'!AX12,'كـشـف حضور يومي'!BD12,'كـشـف حضور يومي'!BJ12,'كـشـف حضور يومي'!BP12,'كـشـف حضور يومي'!BV12,'كـشـف حضور يومي'!CB12,'كـشـف حضور يومي'!CH12,'كـشـف حضور يومي'!CN12,'كـشـف حضور يومي'!CT12,'كـشـف حضور يومي'!CZ12,'كـشـف حضور يومي'!DF12,'كـشـف حضور يومي'!DL12,'كـشـف حضور يومي'!DR12,'كـشـف حضور يومي'!DX12,'كـشـف حضور يومي'!ED12,'كـشـف حضور يومي'!EJ12,'كـشـف حضور يومي'!EP12,'كـشـف حضور يومي'!EV12,'كـشـف حضور يومي'!FB12,'كـشـف حضور يومي'!FH12,'كـشـف حضور يومي'!FN12,'كـشـف حضور يومي'!FT12,'كـشـف حضور يومي'!FZ12,'كـشـف حضور يومي'!GF12) -> 0 | G14: =F14-مراجع!$A$2 -> -8.6666667 | H14: =مراجع!$A$2-F14 -> 8.6666667 | I14: =COUNTIFS('كـشـف حضور يومي'!D12:GG12, "*حضور*") -> 0 | J14: =COUNTIF('كـشـف حضور يومي'!D12:GG12,$J$5) -> 0 | K14: =COUNTIF('كـشـف حضور يومي'!D12:GG12,مراجع!$E$3) -> 0 | L14: =COUNTIF('كـشـف حضور يومي'!D12:GG12,مراجع!$K$3) -> 0 | M14: =مراجع!$C$2-J14 -> 7 | N14: =مراجع!$D$2-K14 -> 21 | O14: =COUNTIF('كـشـف حضور يومي'!D12:GG12,مراجع!$F$3) -> 0 | P14: =COUNTIFS('كـشـف حضور يومي'!D12:GG12, "*الجمعة*") -> 0 | Q14: =COUNTIFS('كـشـف حضور يومي'!D12:GG12, "*السبت*") -> 0 | R14: =COUNTIFS('كـشـف حضور يومي'!D12:GG12, "*مأمورية*") -> 0
B15: 11 | C15: أحمد نبوي | D15: خدمات معاونة | E15: القرض الفرنسي | F15: =SUM('كـشـف حضور يومي'!H13,'كـشـف حضور يومي'!N13,'كـشـف حضور يومي'!T13,'كـشـف حضور يومي'!Z13,'كـشـف حضور يومي'!AF13,'كـشـف حضور يومي'!AL13,'كـشـف حضور يومي'!AR13,'كـشـف حضور يومي'!AX13,'كـشـف حضور يومي'!BD13,'كـشـف حضور يومي'!BJ13,'كـشـف حضور يومي'!BP13,'كـشـف حضور يومي'!BV13,'كـشـف حضور يومي'!CB13,'كـشـف حضور يومي'!CH13,'كـشـف حضور يومي'!CN13,'كـشـف حضور يومي'!CT13,'كـشـف حضور يومي'!CZ13,'كـشـف حضور يومي'!DF13,'كـشـف حضور يومي'!DL13,'كـشـف حضور يومي'!DR13,'كـشـف حضور يومي'!DX13,'كـشـف حضور يومي'!ED13,'كـشـف حضور يومي'!EJ13,'كـشـف حضور يومي'!EP13,'كـشـف حضور يومي'!EV13,'كـشـف حضور يومي'!FB13,'كـشـف حضور يومي'!FH13,'كـشـف حضور يومي'!FN13,'كـشـف حضور يومي'!FT13,'كـشـف حضور يومي'!FZ13,'كـشـف حضور يومي'!GF13) -> 0 | G15: =F15-مراجع!$A$2 -> -8.6666667 | H15: =مراجع!$A$2-F15 -> 8.6666667 | I15: =COUNTIFS('كـشـف حضور يومي'!D13:GG13, "*حضور*") -> 0 | J15: =COUNTIF('كـشـف حضور يومي'!D13:GG13,$J$5) -> 0 | K15: =COUNTIF('كـشـف حضور يومي'!D13:GG13,مراجع!$E$3) -> 0 | L15: =COUNTIF('كـشـف حضور يومي'!D13:GG13,مراجع!$K$3) -> 0 | M15: =مراجع!$C$2-J15 -> 7 | N15: =مراجع!$D$2-K15 -> 21 | O15: =COUNTIF('كـشـف حضور يومي'!D13:GG13,مراجع!$F$3) -> 0 | P15: =COUNTIFS('كـشـف حضور يومي'!D13:GG13, "*الجمعة*") -> 0 | Q15: =COUNTIFS('كـشـف حضور يومي'!D13:GG13, "*السبت*") -> 0 | R15: =COUNTIFS('كـشـف حضور يومي'!D13:GG13, "*مأمورية*") -> 0
B16: 12 | C16: محمد إبراهيم | D16: خدمات معاونة | E16: القرض الفرنسي | F16: =SUM('كـشـف حضور يومي'!H14,'كـشـف حضور يومي'!N14,'كـشـف حضور يومي'!T14,'كـشـف حضور يومي'!Z14,'كـشـف حضور يومي'!AF14,'كـشـف حضور يومي'!AL14,'كـشـف حضور يومي'!AR14,'كـشـف حضور يومي'!AX14,'كـشـف حضور يومي'!BD14,'كـشـف حضور يومي'!BJ14,'كـشـف حضور يومي'!BP14,'كـشـف حضور يومي'!BV14,'كـشـف حضور يومي'!CB14,'كـشـف حضور يومي'!CH14,'كـشـف حضور يومي'!CN14,'كـشـف حضور يومي'!CT14,'كـشـف حضور يومي'!CZ14,'كـشـف حضور يومي'!DF14,'كـشـف حضور يومي'!DL14,'كـشـف حضور يومي'!DR14,'كـشـف حضور يومي'!DX14,'كـشـف حضور يومي'!ED14,'كـشـف حضور يومي'!EJ14,'كـشـف حضور يومي'!EP14,'كـشـف حضور يومي'!EV14,'كـشـف حضور يومي'!FB14,'كـشـف حضور يومي'!FH14,'كـشـف حضور يومي'!FN14,'كـشـف حضور يومي'!FT14,'كـشـف حضور يومي'!FZ14,'كـشـف حضور يومي'!GF14) -> 0 | G16: =F16-مراجع!$A$2 -> -8.6666667 | H16: =مراجع!$A$2-F16 -> 8.6666667 | I16: =COUNTIFS('كـشـف حضور يومي'!D14:GG14, "*حضور*") -> 0 | J16: =COUNTIF('كـشـف حضور يومي'!D14:GG14,$J$5) -> 0 | K16: =COUNTIF('كـشـف حضور يومي'!D14:GG14,مراجع!$E$3) -> 0 | L16: =COUNTIF('كـشـف حضور يومي'!D14:GG14,مراجع!$K$3) -> 0 | M16: =مراجع!$C$2-J16 -> 7 | N16: =مراجع!$D$2-K16 -> 21 | O16: =COUNTIF('كـشـف حضور يومي'!D14:GG14,مراجع!$F$3) -> 0 | P16: =COUNTIFS('كـشـف حضور يومي'!D14:GG14, "*الجمعة*") -> 0 | Q16: =COUNTIFS('كـشـف حضور يومي'!D14:GG14, "*السبت*") -> 0 | R16: =COUNTIFS('كـشـف حضور يومي'!D14:GG14, "*مأمورية*") -> 0
B18: إســــــــــم الــــــــــمــــــــــوظــــــــــف
B19: كريم محمود
B20: الوظيفة | D20: المشروع | E20: إجمالي | J20: غيابات | M20: رصيد إجازات | O20: إجازات رسمية
B21: =VLOOKUP(B19,C6:D16,2,0) -> سكرتير | D21: =VLOOKUP(B19,C6:E16,3,0) -> البنك الدولي | E21: ساعات الحضور | G21: إضافي | H21: خصم | I21: حضور | J21: عارضة | K21: إعتيادي | L21: بدون إذن | M21: عارضة | N21: إعتيادي
E22: =VLOOKUP(B19,C6:F16,4,0) -> 8.3333333 | G22: =VLOOKUP(B19,C6:G16,5,0) -> -0.33333333 | H22: =VLOOKUP(B19,C6:H16,6,0) -> 0.33333333 | I22: =VLOOKUP(B19,C6:N16,7,0) -> 0 | J22: =VLOOKUP(B19,C6:N16,8,0) -> 0 | K22: =VLOOKUP(B19,C6:N16,9,0) -> 0 | L22: =VLOOKUP(B19,C6:N16,10,0) -> 0 | M22: =VLOOKUP(B19,C6:N16,11,0) -> 7 | N22: =VLOOKUP(B19,C6:N16,12,0) -> 21 | O22: =VLOOKUP(B19,C6:O16,13,0) -> 0
B23: أيام الجمعة | F23: =VLOOKUP(B19,C6:Q16,13,0) -> 0 | H23: أيام السبت | L23: =VLOOKUP(B19,C6:Q16,14,0) -> 0
B24: أيام الإجازات الرسمية | F24: =VLOOKUP(B19,C6:O16,12,0) -> 21 | H24: مأموريات | L24: =VLOOKUP(B19,C6:R16,15,0) -> 0
B25: الـــــــراتـــــــب | H25: =VLOOKUP(B19,'حصر شهري'!A3:M14,11,0) -> 3000

Sheet كريم
A1: المشروع | C1: - | G1: الوظيفة | I1: -
A2: الراتب | C2: - | G2: أجر الساعة | I2: 15
A3: كريم محمود
A4: الشهر | C4: يناير | F4: العام | H4: -
A5: التاريخ | B5: اليوم | D5: حضور | E5: انصراف | F5: إضافي | G5: خصم | H5: إجمالي | I5: ملاحظات
A6: ='كـشـف حضور يومي'!D1 -> 1 | B6: ='كـشـف حضور يومي'!D2 -> السبت | D6: ='كـشـف حضور يومي'!D4 -> 0.375 | E6: ='كـشـف حضور يومي'!E4 -> 0.70833333 | F6: =H6-مراجع!$B$2 -> 0 | G6: =مراجع!$B$2-H6 -> 0 | H6: =SUM(E6-D6) -> 0.33333333 | I6: ='كـشـف حضور يومي'!I4 -> 0
A7: ='كـشـف حضور يومي'!J1 -> 1 | B7: ='كـشـف حضور يومي'!J2 -> السبت | D7: ='كـشـف حضور يومي'!J4 -> 0.375 | E7: ='كـشـف حضور يومي'!K4 -> 0.70833333 | F7: =H7-مراجع!$B$2 -> 0 | G7: =مراجع!$B$2-H7 -> 0 | H7: =SUM(E7-D7) -> 0.33333333 | I7: ='كـشـف حضور يومي'!O4 -> 0
A8: ='كـشـف حضور يومي'!P1 -> 1 | B8: ='كـشـف حضور يومي'!P2 -> السبت | D8: ='كـشـف حضور يومي'!P4 -> 0.375 | E8: ='كـشـف حضور يومي'!Q4 -> 0.70833333 | F8: =H8-مراجع!$B$2 -> 0 | G8: =مراجع!$B$2-H8 -> 0 | H8: =SUM(E8-D8) -> 0.33333333 | I8: ='كـشـف حضور يومي'!U4 -> 0
A9: ='كـشـف حضور يومي'!V1 -> 1 | B9: ='كـشـف حضور يومي'!V2 -> السبت | D9: ='كـشـف حضور يومي'!V4 -> 0.375 | E9: ='كـشـف حضور يومي'!W4 -> 0.70833333 | F9: =H9-مراجع!$B$2 -> 0 | G9: =مراجع!$B$2-H9 -> 0 | H9: =SUM(E9-D9) -> 0.33333333 | I9: ='كـشـف حضور يومي'!AA4 -> 0
A10: ='كـشـف حضور يومي'!AB1 -> 1 | B10: ='كـشـف حضور يومي'!AB2 -> السبت | D10: ='كـشـف حضور يومي'!AB4 -> 0.375 | E10: ='كـشـف حضور يومي'!AC4 -> 0.70833333 | F10: =H10-مراجع!$B$2 -> 0 | G10: =مراجع!$B$2-H10 -> 0 | H10: =SUM(E10-D10) -> 0.33333333 | I10: ='كـشـف حضور يومي'!AG4 -> 0
A11: ='كـشـف حضور يومي'!AH1 -> 1 | B11: ='كـشـف حضور يومي'!AH2 -> السبت | D11: ='كـشـف حضور يومي'!AH4 -> 0.375 | E11: ='كـشـف حضور يومي'!AI4 -> 0.70833333 | F11: =H11-مراجع!$B$2 -> 0 | G11: =مراجع!$B$2-H11 -> 0 | H11: =SUM(E11-D11) -> 0.33333333 | I11: ='كـشـف حضور يومي'!AM4 -> 0
A12: ='كـشـف حضور يومي'!AN1 -> 1 | B12: ='كـشـف حضور يومي'!AN2 -> السبت | D12: ='كـشـف حضور يومي'!AN4 -> 0.375 | E12: ='كـشـف حضور يومي'!AO4 -> 0.70833333 | F12: =H12-مراجع!$B$2 -> 0 | G12: =مراجع!$B$2-H12 -> 0 | H12: =SUM(E12-D12) -> 0.33333333 | I12: ='كـشـف حضور يومي'!AS4 -> 0
A13: ='كـشـف حضور يومي'!AT1 -> 1 | B13: ='كـشـف حضور يومي'!AT2 -> السبت | D13: ='كـشـف حضور يومي'!AT4 -> 0.375 | E13: ='كـشـف حضور يومي'!AU4 -> 0.70833333 | F13: =H13-مراجع!$B$2 -> 0 | G13: =مراجع!$B$2-H13 -> 0 | H13: =SUM(E13-D13) -> 0.33333333 | I13: ='كـشـف حضور يومي'!AY4 -> 0
A14: ='كـشـف حضور يومي'!AZ1 -> 1 | B14: ='كـشـف حضور يومي'!AZ2 -> السبت | D14: ='كـشـف حضور يومي'!AZ4 -> 0.375 | E14: ='كـشـف حضور يومي'!BA4 -> 0.70833333 | F14: =H14-مراجع!$B$2 -> 0 | G14: =مراجع!$B$2-H14 -> 0 | H14: =SUM(E14-D14) -> 0.33333333 | I14: ='كـشـف حضور يومي'!BE4 -> 0
A15: ='كـشـف حضور يومي'!BF1 -> 1 | B15: ='كـشـف حضور يومي'!BF2 -> السبت | D15: ='كـشـف حضور يومي'!BF4 -> 0.375 | E15: ='كـشـف حضور يومي'!BG4 -> 0.70833333 | F15: =H15-مراجع!$B$2 -> 0 | G15: =مراجع!$B$2-H15 -> 0 | H15: =SUM(E15-D15) -> 0.33333333 | I15: ='كـشـف حضور يومي'!BK4 -> 0
A16: ='كـشـف حضور يومي'!BL1 -> 1 | B16: ='كـشـف حضور يومي'!BL2 -> السبت | D16: ='كـشـف حضور يومي'!BL4 -> 0.375 | E16: ='كـشـف حضور يومي'!BM4 -> 0.70833333 | F16: =H16-مراجع!$B$2 -> 0 | G16: =مراجع!$B$2-H16 -> 0 | H16: =SUM(E16-D16) -> 0.33333333 | I16: ='كـشـف حضور يومي'!BQ4 -> 0
A17: ='كـشـف حضور يومي'!BR1 -> 1 | B17: ='كـشـف حضور يومي'!BR2 -> السبت | D17: ='كـشـف حضور يومي'!BR4 -> 0.375 | E17: ='كـشـف حضور يومي'!BS4 -> 0.70833333 | F17: =H17-مراجع!$B$2 -> 0 | G17: =مراجع!$B$2-H17 -> 0 | H17: =SUM(E17-D17) -> 0.33333333 | I17: ='كـشـف حضور يومي'!BW4 -> 0
